Workbook

Sheet 封皮
A2: 研 发 费 辅 助 账
A5: 二〇二五年度
A8: 公司名称:

Sheet 立项
A2: 序号 | B2: 项目名称 | C2: 研发周期 | D2: 人员人工 | E2: 直接投入 | F2: 折旧费用 | G2: 其他费用 | H2: 合计 | I2: 研发人员
A3: RD01 | D3: ='人员人工-研发人员工资'!H475+'人员人工-研发人员社保'!H475+'人员人工-研发人员公积金'!H475 -> 0 | E3: ='直接投入-领料'!B4+'直接投入-动力'!H30 -> 0 | F3: =RD01!I114 -> 0 | G3: =其他费用!B15 -> 0 | H3: =SUM(D3:G3) -> 0
A4: RD02 | D4: ='人员人工-研发人员工资'!J475+'人员人工-研发人员社保'!J475+'人员人工-研发人员公积金'!J475 -> 0 | E4: ='直接投入-领料'!B5+'直接投入-动力'!I30 -> 0 | F4: =RD02!I114 -> 0 | G4: =其他费用!C15 -> 0 | H4: =SUM(D4:G4) -> 0
A5: RD03 | D5: ='人员人工-研发人员工资'!L475+'人员人工-研发人员社保'!L475+'人员人工-研发人员公积金'!L475 -> 0 | E5: ='直接投入-领料'!B6+'直接投入-动力'!J30 -> 0 | F5: =RD03!I114 -> 0 | G5: =其他费用!D15 -> 0 | H5: =SUM(D5:G5) -> 0
A6: RD04 | D6: ='人员人工-研发人员工资'!N475+'人员人工-研发人员社保'!N475+'人员人工-研发人员公积金'!N475 -> 0 | E6: ='直接投入-领料'!B7+'直接投入-动力'!K30 -> 0 | F6: =RD04!I114 -> 0 | G6: =其他费用!E15 -> 0 | H6: =SUM(D6:G6) -> 0
A7: RD05 | D7: ='人员人工-研发人员工资'!P475+'人员人工-研发人员社保'!P475+'人员人工-研发人员公积金'!P475 -> 0 | E7: ='直接投入-领料'!B8+'直接投入-动力'!L30 -> 0 | F7: =RD05!I114 -> 0 | G7: =其他费用!F15 -> 0 | H7: =SUM(D7:G7) -> 0
A8: RD06 | D8: ='人员人工-研发人员工资'!R475+'人员人工-研发人员社保'!R475+'人员人工-研发人员公积金'!R475 -> 0 | E8: ='直接投入-领料'!B9+'直接投入-动力'!M30 -> 0 | F8: =RD06!I114 -> 0 | G8: =其他费用!G15 -> 0 | H8: =SUM(D8:G8) -> 0
A9: RD07 | D9: ='人员人工-研发人员工资'!T475+'人员人工-研发人员社保'!T475+'人员人工-研发人员公积金'!T475 -> 0 | E9: ='直接投入-领料'!B10+'直接投入-动力'!N30 -> 0 | F9: =RD07!I114 -> 0 | G9: =其他费用!H15 -> 0 | H9: =SUM(D9:G9) -> 0
A10: RD08 | D10: ='人员人工-研发人员工资'!V475+'人员人工-研发人员社保'!V475+'人员人工-研发人员公积金'!V475 -> 0 | E10: ='直接投入-领料'!B11+'直接投入-动力'!O30 -> 0 | F10: =RD08!I114 -> 0 | G10: =其他费用!I15 -> 0 | H10: =SUM(D10:G10) -> 0
A11: RD09 | D11: ='人员人工-研发人员工资'!X475+'人员人工-研发人员社保'!X475+'人员人工-研发人员公积金'!X475 -> 0 | E11: ='直接投入-领料'!B12+'直接投入-动力'!P30 -> 0 | F11: =RD09!I114 -> 0 | G11: =其他费用!J15 -> 0 | H11: =SUM(D11:G11) -> 0
A12: RD10 | D12: ='人员人工-研发人员工资'!Z475+'人员人工-研发人员社保'!Z475+'人员人工-研发人员公积金'!Z475 -> 0 | E12: ='直接投入-领料'!B13+'直接投入-动力'!Q30 -> 0 | F12: =RD10!I114 -> 0 | G12: =其他费用!K15 -> 0 | H12: =SUM(D12:G12) -> 0
A13: 合计 | D13: =SUM(D3:D12) -> 0 | E13: =SUM(E3:E12) -> 0 | F13: =SUM(F3:F12) -> 0 | G13: =SUM(G3:G12) -> 0 | H13: =SUM(H3:H12) -> 0
F14: 营业收入
F15: 占比 | H15: =H13/H14 -> #DIV/0!
A16: 调账科目：工资--、社保--、公积金--、折旧--、动力--、材料--；调账金额最后一张表
A17: 附件：人员人工-研发人员工资中每月分摊表附计提工资凭证后，人员人工-研发人员社保中每月分摊表附计提社保凭证后，人员人工-研发人员公积金中每月分摊表附计提公积金凭证后，研发设备折旧表中每月研发折旧明细表附计提折旧凭证后，直接投入-动力中每月动力费分配表附计提电费凭证后，领料单打印版（最好买一式三联单据手写，该项目研发人员签字）附生产成本结转凭证后
A18: 汇算清缴107012表第一行填写此表中RD个数，第3行人员人工费用、第7行直接投入费用、第16行折旧费用、第28行其他费用按照上表合计数填写
A19: 辅助账打印：封皮、立项、各RD表带绿色标签
A20: 其他打印留存
D22: =ROUND(D3/10000,2) -> 0 | E22: =ROUND(E3/10000,2) -> 0 | F22: =ROUND(F3/10000,2) -> 0 | G22: =ROUND(G3/10000,2) -> 0 | H22: =ROUND(H3/10000,2) -> 0
D23: =ROUND(D4/10000,2) -> 0 | E23: =ROUND(E4/10000,2) -> 0 | F23: =ROUND(F4/10000,2) -> 0 | G23: =ROUND(G4/10000,2) -> 0 | H23: =ROUND(H4/10000,2) -> 0
D24: =ROUND(D5/10000,2) -> 0 | E24: =ROUND(E5/10000,2) -> 0 | F24: =ROUND(F5/10000,2) -> 0 | G24: =ROUND(G5/10000,2) -> 0 | H24: =ROUND(H5/10000,2) -> 0
D25: =ROUND(D6/10000,2) -> 0 | E25: =ROUND(E6/10000,2) -> 0 | F25: =ROUND(F6/10000,2) -> 0 | G25: =ROUND(G6/10000,2) -> 0 | H25: =ROUND(H6/10000,2) -> 0
D26: =ROUND(D7/10000,2) -> 0 | E26: =ROUND(E7/10000,2) -> 0 | F26: =ROUND(F7/10000,2) -> 0 | G26: =ROUND(G7/10000,2) -> 0 | H26: =ROUND(H7/10000,2) -> 0
D27: =ROUND(D8/10000,2) -> 0 | E27: =ROUND(E8/10000,2) -> 0 | F27: =ROUND(F8/10000,2) -> 0 | G27: =ROUND(G8/10000,2) -> 0 | H27: =ROUND(H8/10000,2) -> 0
D28: =ROUND(D9/10000,2) -> 0 | E28: =ROUND(E9/10000,2) -> 0 | F28: =ROUND(F9/10000,2) -> 0 | G28: =ROUND(G9/10000,2) -> 0 | H28: =ROUND(H9/10000,2) -> 0
D29: =ROUND(D10/10000,2) -> 0 | E29: =ROUND(E10/10000,2) -> 0 | F29: =ROUND(F10/10000,2) -> 0 | G29: =ROUND(G10/10000,2) -> 0 | H29: =ROUND(H10/10000,2) -> 0
D30: =ROUND(D11/10000,2) -> 0 | E30: =ROUND(E11/10000,2) -> 0 | F30: =ROUND(F11/10000,2) -> 0 | G30: =ROUND(G11/10000,2) -> 0 | H30: =ROUND(H11/10000,2) -> 0
D31: =ROUND(D12/10000,2) -> 0 | E31: =ROUND(E12/10000,2) -> 0 | F31: =ROUND(F12/10000,2) -> 0 | G31: =ROUND(G12/10000,2) -> 0 | H31: =ROUND(H12/10000,2) -> 0

Sheet 人员人工-研发人员工资
B1: 2025年1月份研发人员工资项目分摊表
A3: 序号 | B3: 姓名 | C3: 月工资 | D3: 出勤天数 | E3: 研发天数合计 | F3: 研发工资合计 | G3: =立项!$A$3 -> RD01 | I3: =立项!$A$4 -> RD02 | K3: =立项!$A$5 -> RD03 | M3: =立项!$A$6 -> RD04 | O3: =立项!$A$7 -> RD05 | Q3: =立项!$A$8 -> RD06 | S3: =立项!$A$9 -> RD07 | U3: =立项!$A$10 -> RD08 | W3: =立项!$A$11 -> RD09 | Y3: =立项!$A$12 -> RD10 | AA3: 核对公式 | AB3: 研发人员工资表
G4: =立项!C3 -> 0 | I4: =立项!C4 -> 0 | K4: =立项!C5 -> 0 | M4: =立项!C6 -> 0 | O4: =立项!C7 -> 0 | Q4: =立项!C8 -> 0 | S4: =立项!C9 -> 0 | U4: =立项!C10 -> 0 | W4: =立项!C11 -> 0 | Y4: =立项!C12 -> 0
G5: 研发天数 | H5: 研发工资 | I5: 研发天数 | J5: 研发工资 | K5: 研发天数 | L5: 研发工资 | M5: 研发天数 | N5: 研发工资 | O5: 研发天数 | P5: 研发工资 | Q5: 研发天数 | R5: 研发工资 | S5: 研发天数 | T5: 研发工资 | U5: 研发天数 | V5: 研发工资 | W5: 研发天数 | X5: 研发工资 | Y5: 研发天数 | Z5: 研发工资 | AB5: 姓名 | AC5: 1月 | AD5: 2月 | AE5: 3月 | AF5: 4月 | AG5: 5月 | AH5: 6月 | AI5: 7月 | AJ5: 8月 | AK5: 9月 | AL5: 10月 | AM5: 11月 | AN5: 12月 | AO5: 合计
A6: 1 | E6: =G6+I6+K6+M6+O6+Q6+S6+U6+W6+Y6 -> 0 | F6: =H6+J6+L6+N6+P6+R6+T6+V6+X6+Z6 -> 0 | H6: =IF($D6=0,0,ROUND(G6/$D6*$C6,2)) -> 0 | J6: =IF($D6=0,0,ROUND(I6/$D6*$C6,2)) -> 0 | L6: =IF($D6=0,0,ROUND(K6/$D6*$C6,2)) -> 0 | N6: =IF($D6=0,0,ROUND(M6/$D6*$C6,2)) -> 0 | P6: =IF($D6=0,0,ROUND(O6/$D6*$C6,2)) -> 0 | R6: =IF($D6=0,0,ROUND(Q6/$D6*$C6,2)) -> 0 | T6: =IF($D6=0,0,ROUND(S6/$D6*$C6,2)) -> 0 | V6: =IF($D6=0,0,ROUND(U6/$D6*$C6,2)) -> 0 | X6: =IF($D6=0,0,ROUND(W6/$D6*$C6,2)) -> 0 | Z6: =IF($D6=0,0,ROUND(Y6/$D6*$C6,2)) -> 0 | AA6: =D6-E6 -> 0 | AO6: =SUM(AC6:AN6) -> 0
A7: 2 | E7: =G7+I7+K7+M7+O7+Q7+S7+U7+W7+Y7 -> 0 | F7: =H7+J7+L7+N7+P7+R7+T7+V7+X7+Z7 -> 0 | H7: =IF($D7=0,0,ROUND(G7/$D7*$C7,2)) -> 0 | J7: =IF($D7=0,0,ROUND(I7/$D7*$C7,2)) -> 0 | L7: =IF($D7=0,0,ROUND(K7/$D7*$C7,2)) -> 0 | N7: =IF($D7=0,0,ROUND(M7/$D7*$C7,2)) -> 0 | P7: =IF($D7=0,0,ROUND(O7/$D7*$C7,2)) -> 0 | R7: =IF($D7=0,0,ROUND(Q7/$D7*$C7,2)) -> 0 | T7: =IF($D7=0,0,ROUND(S7/$D7*$C7,2)) -> 0 | V7: =IF($D7=0,0,ROUND(U7/$D7*$C7,2)) -> 0 | X7: =IF($D7=0,0,ROUND(W7/$D7*$C7,2)) -> 0 | Z7: =IF($D7=0,0,ROUND(Y7/$D7*$C7,2)) -> 0 | AA7: =D7-E7 -> 0 | AO7: =SUM(AC7:AN7) -> 0
A8: 3 | E8: =G8+I8+K8+M8+O8+Q8+S8+U8+W8+Y8 -> 0 | F8: =H8+J8+L8+N8+P8+R8+T8+V8+X8+Z8 -> 0 | H8: =IF($D8=0,0,ROUND(G8/$D8*$C8,2)) -> 0 | J8: =IF($D8=0,0,ROUND(I8/$D8*$C8,2)) -> 0 | L8: =IF($D8=0,0,ROUND(K8/$D8*$C8,2)) -> 0 | N8: =IF($D8=0,0,ROUND(M8/$D8*$C8,2)) -> 0 | P8: =IF($D8=0,0,ROUND(O8/$D8*$C8,2)) -> 0 | R8: =IF($D8=0,0,ROUND(Q8/$D8*$C8,2)) -> 0 | T8: =IF($D8=0,0,ROUND(S8/$D8*$C8,2)) -> 0 | V8: =IF($D8=0,0,ROUND(U8/$D8*$C8,2)) -> 0 | X8: =IF($D8=0,0,ROUND(W8/$D8*$C8,2)) -> 0 | Z8: =IF($D8=0,0,ROUND(Y8/$D8*$C8,2)) -> 0 | AA8: =D8-E8 -> 0 | AO8: =SUM(AC8:AN8) -> 0
A9: 4 | E9: =G9+I9+K9+M9+O9+Q9+S9+U9+W9+Y9 -> 0 | F9: =H9+J9+L9+N9+P9+R9+T9+V9+X9+Z9 -> 0 | H9: =IF($D9=0,0,ROUND(G9/$D9*$C9,2)) -> 0 | J9: =IF($D9=0,0,ROUND(I9/$D9*$C9,2)) -> 0 | L9: =IF($D9=0,0,ROUND(K9/$D9*$C9,2)) -> 0 | N9: =IF($D9=0,0,ROUND(M9/$D9*$C9,2)) -> 0 | P9: =IF($D9=0,0,ROUND(O9/$D9*$C9,2)) -> 0 | R9: =IF($D9=0,0,ROUND(Q9/$D9*$C9,2)) -> 0 | T9: =IF($D9=0,0,ROUND(S9/$D9*$C9,2)) -> 0 | V9: =IF($D9=0,0,ROUND(U9/$D9*$C9,2)) -> 0 | X9: =IF($D9=0,0,ROUND(W9/$D9*$C9,2)) -> 0 | Z9: =IF($D9=0,0,ROUND(Y9/$D9*$C9,2)) -> 0 | AA9: =D9-E9 -> 0 | AO9: =SUM(AC9:AN9) -> 0
A10: 5 | E10: =G10+I10+K10+M10+O10+Q10+S10+U10+W10+Y10 -> 0 | F10: =H10+J10+L10+N10+P10+R10+T10+V10+X10+Z10 -> 0 | H10: =IF($D10=0,0,ROUND(G10/$D10*$C10,2)) -> 0 | J10: =IF($D10=0,0,ROUND(I10/$D10*$C10,2)) -> 0 | L10: =IF($D10=0,0,ROUND(K10/$D10*$C10,2)) -> 0 | N10: =IF($D10=0,0,ROUND(M10/$D10*$C10,2)) -> 0 | P10: =IF($D10=0,0,ROUND(O10/$D10*$C10,2)) -> 0 | R10: =IF($D10=0,0,ROUND(Q10/$D10*$C10,2)) -> 0 | T10: =IF($D10=0,0,ROUND(S10/$D10*$C10,2)) -> 0 | V10: =IF($D10=0,0,ROUND(U10/$D10*$C10,2)) -> 0 | X10: =IF($D10=0,0,ROUND(W10/$D10*$C10,2)) -> 0 | Z10: =IF($D10=0,0,ROUND(Y10/$D10*$C10,2)) -> 0 | AA10: =D10-E10 -> 0 | AO10: =SUM(AC10:AN10) -> 0
A11: 6 | E11: =G11+I11+K11+M11+O11+Q11+S11+U11+W11+Y11 -> 0 | F11: =H11+J11+L11+N11+P11+R11+T11+V11+X11+Z11 -> 0 | H11: =IF($D11=0,0,ROUND(G11/$D11*$C11,2)) -> 0 | J11: =IF($D11=0,0,ROUND(I11/$D11*$C11,2)) -> 0 | L11: =IF($D11=0,0,ROUND(K11/$D11*$C11,2)) -> 0 | N11: =IF($D11=0,0,ROUND(M11/$D11*$C11,2)) -> 0 | P11: =IF($D11=0,0,ROUND(O11/$D11*$C11,2)) -> 0 | R11: =IF($D11=0,0,ROUND(Q11/$D11*$C11,2)) -> 0 | T11: =IF($D11=0,0,ROUND(S11/$D11*$C11,2)) -> 0 | V11: =IF($D11=0,0,ROUND(U11/$D11*$C11,2)) -> 0 | X11: =IF($D11=0,0,ROUND(W11/$D11*$C11,2)) -> 0 | Z11: =IF($D11=0,0,ROUND(Y11/$D11*$C11,2)) -> 0 | AA11: =D11-E11 -> 0 | AO11: =SUM(AC11:AN11) -> 0
A12: 7 | E12: =G12+I12+K12+M12+O12+Q12+S12+U12+W12+Y12 -> 0 | F12: =H12+J12+L12+N12+P12+R12+T12+V12+X12+Z12 -> 0 | H12: =IF($D12=0,0,ROUND(G12/$D12*$C12,2)) -> 0 | J12: =IF($D12=0,0,ROUND(I12/$D12*$C12,2)) -> 0 | L12: =IF($D12=0,0,ROUND(K12/$D12*$C12,2)) -> 0 | N12: =IF($D12=0,0,ROUND(M12/$D12*$C12,2)) -> 0 | P12: =IF($D12=0,0,ROUND(O12/$D12*$C12,2)) -> 0 | R12: =IF($D12=0,0,ROUND(Q12/$D12*$C12,2)) -> 0 | T12: =IF($D12=0,0,ROUND(S12/$D12*$C12,2)) -> 0 | V12: =IF($D12=0,0,ROUND(U12/$D12*$C12,2)) -> 0 | X12: =IF($D12=0,0,ROUND(W12/$D12*$C12,2)) -> 0 | Z12: =IF($D12=0,0,ROUND(Y12/$D12*$C12,2)) -> 0 | AA12: =D12-E12 -> 0 | AO12: =SUM(AC12:AN12) -> 0
A13: 8 | E13: =G13+I13+K13+M13+O13+Q13+S13+U13+W13+Y13 -> 0 | F13: =H13+J13+L13+N13+P13+R13+T13+V13+X13+Z13 -> 0 | H13: =IF($D13=0,0,ROUND(G13/$D13*$C13,2)) -> 0 | J13: =IF($D13=0,0,ROUND(I13/$D13*$C13,2)) -> 0 | L13: =IF($D13=0,0,ROUND(K13/$D13*$C13,2)) -> 0 | N13: =IF($D13=0,0,ROUND(M13/$D13*$C13,2)) -> 0 | P13: =IF($D13=0,0,ROUND(O13/$D13*$C13,2)) -> 0 | R13: =IF($D13=0,0,ROUND(Q13/$D13*$C13,2)) -> 0 | T13: =IF($D13=0,0,ROUND(S13/$D13*$C13,2)) -> 0 | V13: =IF($D13=0,0,ROUND(U13/$D13*$C13,2)) -> 0 | X13: =IF($D13=0,0,ROUND(W13/$D13*$C13,2)) -> 0 | Z13: =IF($D13=0,0,ROUND(Y13/$D13*$C13,2)) -> 0 | AA13: =D13-E13 -> 0 | AO13: =SUM(AC13:AN13) -> 0
A14: 9 | E14: =G14+I14+K14+M14+O14+Q14+S14+U14+W14+Y14 -> 0 | F14: =H14+J14+L14+N14+P14+R14+T14+V14+X14+Z14 -> 0 | H14: =IF($D14=0,0,ROUND(G14/$D14*$C14,2)) -> 0 | J14: =IF($D14=0,0,ROUND(I14/$D14*$C14,2)) -> 0 | L14: =IF($D14=0,0,ROUND(K14/$D14*$C14,2)) -> 0 | N14: =IF($D14=0,0,ROUND(M14/$D14*$C14,2)) -> 0 | P14: =IF($D14=0,0,ROUND(O14/$D14*$C14,2)) -> 0 | R14: =IF($D14=0,0,ROUND(Q14/$D14*$C14,2)) -> 0 | T14: =IF($D14=0,0,ROUND(S14/$D14*$C14,2)) -> 0 | V14: =IF($D14=0,0,ROUND(U14/$D14*$C14,2)) -> 0 | X14: =IF($D14=0,0,ROUND(W14/$D14*$C14,2)) -> 0 | Z14: =IF($D14=0,0,ROUND(Y14/$D14*$C14,2)) -> 0 | AA14: =D14-E14 -> 0 | AO14: =SUM(AC14:AN14) -> 0
A15: 10 | E15: =G15+I15+K15+M15+O15+Q15+S15+U15+W15+Y15 -> 0 | F15: =H15+J15+L15+N15+P15+R15+T15+V15+X15+Z15 -> 0 | H15: =IF($D15=0,0,ROUND(G15/$D15*$C15,2)) -> 0 | J15: =IF($D15=0,0,ROUND(I15/$D15*$C15,2)) -> 0 | L15: =IF($D15=0,0,ROUND(K15/$D15*$C15,2)) -> 0 | N15: =IF($D15=0,0,ROUND(M15/$D15*$C15,2)) -> 0 | P15: =IF($D15=0,0,ROUND(O15/$D15*$C15,2)) -> 0 | R15: =IF($D15=0,0,ROUND(Q15/$D15*$C15,2)) -> 0 | T15: =IF($D15=0,0,ROUND(S15/$D15*$C15,2)) -> 0 | V15: =IF($D15=0,0,ROUND(U15/$D15*$C15,2)) -> 0 | X15: =IF($D15=0,0,ROUND(W15/$D15*$C15,2)) -> 0 | Z15: =IF($D15=0,0,ROUND(Y15/$D15*$C15,2)) -> 0 | AA15: =D15-E15 -> 0 | AO15: =SUM(AC15:AN15) -> 0
A16: 11 | E16: =G16+I16+K16+M16+O16+Q16+S16+U16+W16+Y16 -> 0 | F16: =H16+J16+L16+N16+P16+R16+T16+V16+X16+Z16 -> 0 | H16: =IF($D16=0,0,ROUND(G16/$D16*$C16,2)) -> 0 | J16: =IF($D16=0,0,ROUND(I16/$D16*$C16,2)) -> 0 | L16: =IF($D16=0,0,ROUND(K16/$D16*$C16,2)) -> 0 | N16: =IF($D16=0,0,ROUND(M16/$D16*$C16,2)) -> 0 | P16: =IF($D16=0,0,ROUND(O16/$D16*$C16,2)) -> 0 | R16: =IF($D16=0,0,ROUND(Q16/$D16*$C16,2)) -> 0 | T16: =IF($D16=0,0,ROUND(S16/$D16*$C16,2)) -> 0 | V16: =IF($D16=0,0,ROUND(U16/$D16*$C16,2)) -> 0 | X16: =IF($D16=0,0,ROUND(W16/$D16*$C16,2)) -> 0 | Z16: =IF($D16=0,0,ROUND(Y16/$D16*$C16,2)) -> 0 | AA16: =D16-E16 -> 0 | AO16: =SUM(AC16:AN16) -> 0
A17: 12 | E17: =G17+I17+K17+M17+O17+Q17+S17+U17+W17+Y17 -> 0 | F17: =H17+J17+L17+N17+P17+R17+T17+V17+X17+Z17 -> 0 | H17: =IF($D17=0,0,ROUND(G17/$D17*$C17,2)) -> 0 | J17: =IF($D17=0,0,ROUND(I17/$D17*$C17,2)) -> 0 | L17: =IF($D17=0,0,ROUND(K17/$D17*$C17,2)) -> 0 | N17: =IF($D17=0,0,ROUND(M17/$D17*$C17,2)) -> 0 | P17: =IF($D17=0,0,ROUND(O17/$D17*$C17,2)) -> 0 | R17: =IF($D17=0,0,ROUND(Q17/$D17*$C17,2)) -> 0 | T17: =IF($D17=0,0,ROUND(S17/$D17*$C17,2)) -> 0 | V17: =IF($D17=0,0,ROUND(U17/$D17*$C17,2)) -> 0 | X17: =IF($D17=0,0,ROUND(W17/$D17*$C17,2)) -> 0 | Z17: =IF($D17=0,0,ROUND(Y17/$D17*$C17,2)) -> 0 | AA17: =D17-E17 -> 0 | AO17: =SUM(AC17:AN17) -> 0
... A23: 18 | E23: =G23+I23+K23+M23+O23+Q23+S23+U23+W23+Y23 -> 0 | F23: =H23+J23+L23+N23+P23+R23+T23+V23+X23+Z23 -> 0 | H23: =IF($D23=0,0,ROUND(G23/$D23*$C23,2)) -> 0 | J23: =IF($D23=0,0,ROUND(I23/$D23*$C23,2)) -> 0 | L23: =IF($D23=0,0,ROUND(K23/$D23*$C23,2)) -> 0 | N23: =IF($D23=0,0,ROUND(M23/$D23*$C23,2)) -> 0 | P23: =IF($D23=0,0,ROUND(O23/$D23*$C23,2)) -> 0 | R23: =IF($D23=0,0,ROUND(Q23/$D23*$C23,2)) -> 0 | T23: =IF($D23=0,0,ROUND(S23/$D23*$C23,2)) -> 0 | V23: =IF($D23=0,0,ROUND(U23/$D23*$C23,2)) -> 0 | X23: =IF($D23=0,0,ROUND(W23/$D23*$C23,2)) -> 0 | Z23: =IF($D23=0,0,ROUND(Y23/$D23*$C23,2)) -> 0 | AA23: =D23-E23 -> 0 | AO23: =SUM(AC23:AN23) -> 0
A24: 19 | E24: =G24+I24+K24+M24+O24+Q24+S24+U24+W24+Y24 -> 0 | F24: =H24+J24+L24+N24+P24+R24+T24+V24+X24+Z24 -> 0 | H24: =IF($D24=0,0,ROUND(G24/$D24*$C24,2)) -> 0 | J24: =IF($D24=0,0,ROUND(I24/$D24*$C24,2)) -> 0 | L24: =IF($D24=0,0,ROUND(K24/$D24*$C24,2)) -> 0 | N24: =IF($D24=0,0,ROUND(M24/$D24*$C24,2)) -> 0 | P24: =IF($D24=0,0,ROUND(O24/$D24*$C24,2)) -> 0 | R24: =IF($D24=0,0,ROUND(Q24/$D24*$C24,2)) -> 0 | T24: =IF($D24=0,0,ROUND(S24/$D24*$C24,2)) -> 0 | V24: =IF($D24=0,0,ROUND(U24/$D24*$C24,2)) -> 0 | X24: =IF($D24=0,0,ROUND(W24/$D24*$C24,2)) -> 0 | Z24: =IF($D24=0,0,ROUND(Y24/$D24*$C24,2)) -> 0 | AA24: =D24-E24 -> 0 | AO24: =SUM(AC25:AN25) -> 0
A25: 20 | E25: =G25+I25+K25+M25+O25+Q25+S25+U25+W25+Y25 -> 0 | F25: =H25+J25+L25+N25+P25+R25+T25+V25+X25+Z25 -> 0 | H25: =IF($D25=0,0,ROUND(G25/$D25*$C25,2)) -> 0 | J25: =IF($D25=0,0,ROUND(I25/$D25*$C25,2)) -> 0 | L25: =IF($D25=0,0,ROUND(K25/$D25*$C25,2)) -> 0 | N25: =IF($D25=0,0,ROUND(M25/$D25*$C25,2)) -> 0 | P25: =IF($D25=0,0,ROUND(O25/$D25*$C25,2)) -> 0 | R25: =IF($D25=0,0,ROUND(Q25/$D25*$C25,2)) -> 0 | T25: =IF($D25=0,0,ROUND(S25/$D25*$C25,2)) -> 0 | V25: =IF($D25=0,0,ROUND(U25/$D25*$C25,2)) -> 0 | X25: =IF($D25=0,0,ROUND(W25/$D25*$C25,2)) -> 0 | Z25: =IF($D25=0,0,ROUND(Y25/$D25*$C25,2)) -> 0 | AA25: =D25-E25 -> 0 | AO25: =SUM(AC25:AN25) -> 0
A26: 21 | E26: =G26+I26+K26+M26+O26+Q26+S26+U26+W26+Y26 -> 0 | F26: =H26+J26+L26+N26+P26+R26+T26+V26+X26+Z26 -> 0 | H26: =IF($D26=0,0,ROUND(G26/$D26*$C26,2)) -> 0 | J26: =IF($D26=0,0,ROUND(I26/$D26*$C26,2)) -> 0 | L26: =IF($D26=0,0,ROUND(K26/$D26*$C26,2)) -> 0 | N26: =IF($D26=0,0,ROUND(M26/$D26*$C26,2)) -> 0 | P26: =IF($D26=0,0,ROUND(O26/$D26*$C26,2)) -> 0 | R26: =IF($D26=0,0,ROUND(Q26/$D26*$C26,2)) -> 0 | T26: =IF($D26=0,0,ROUND(S26/$D26*$C26,2)) -> 0 | V26: =IF($D26=0,0,ROUND(U26/$D26*$C26,2)) -> 0 | X26: =IF($D26=0,0,ROUND(W26/$D26*$C26,2)) -> 0 | Z26: =IF($D26=0,0,ROUND(Y26/$D26*$C26,2)) -> 0 | AA26: =D26-E26 -> 0 | AO26: =SUM(AC26:AN26) -> 0
A27: 22 | E27: =G27+I27+K27+M27+O27+Q27+S27+U27+W27+Y27 -> 0 | F27: =H27+J27+L27+N27+P27+R27+T27+V27+X27+Z27 -> 0 | H27: =IF($D27=0,0,ROUND(G27/$D27*$C27,2)) -> 0 | J27: =IF($D27=0,0,ROUND(I27/$D27*$C27,2)) -> 0 | L27: =IF($D27=0,0,ROUND(K27/$D27*$C27,2)) -> 0 | N27: =IF($D27=0,0,ROUND(M27/$D27*$C27,2)) -> 0 | P27: =IF($D27=0,0,ROUND(O27/$D27*$C27,2)) -> 0 | R27: =IF($D27=0,0,ROUND(Q27/$D27*$C27,2)) -> 0 | T27: =IF($D27=0,0,ROUND(S27/$D27*$C27,2)) -> 0 | V27: =IF($D27=0,0,ROUND(U27/$D27*$C27,2)) -> 0 | X27: =IF($D27=0,0,ROUND(W27/$D27*$C27,2)) -> 0 | Z27: =IF($D27=0,0,ROUND(Y27/$D27*$C27,2)) -> 0 | AA27: =D27-E27 -> 0 | AO27: =SUM(AC27:AN27) -> 0
A28: 23 | E28: =G28+I28+K28+M28+O28+Q28+S28+U28+W28+Y28 -> 0 | F28: =H28+J28+L28+N28+P28+R28+T28+V28+X28+Z28 -> 0 | H28: =IF($D28=0,0,ROUND(G28/$D28*$C28,2)) -> 0 | J28: =IF($D28=0,0,ROUND(I28/$D28*$C28,2)) -> 0 | L28: =IF($D28=0,0,ROUND(K28/$D28*$C28,2)) -> 0 | N28: =IF($D28=0,0,ROUND(M28/$D28*$C28,2)) -> 0 | P28: =IF($D28=0,0,ROUND(O28/$D28*$C28,2)) -> 0 | R28: =IF($D28=0,0,ROUND(Q28/$D28*$C28,2)) -> 0 | T28: =IF($D28=0,0,ROUND(S28/$D28*$C28,2)) -> 0 | V28: =IF($D28=0,0,ROUND(U28/$D28*$C28,2)) -> 0 | X28: =IF($D28=0,0,ROUND(W28/$D28*$C28,2)) -> 0 | Z28: =IF($D28=0,0,ROUND(Y28/$D28*$C28,2)) -> 0 | AA28: =D28-E28 -> 0 | AO28: =SUM(AC28:AN28) -> 0
A29: 25 | E29: =G29+I29+K29+M29+O29+Q29+S29+U29+W29+Y29 -> 0 | F29: =H29+J29+L29+N29+P29+R29+T29+V29+X29+Z29 -> 0 | H29: =IF($D29=0,0,ROUND(G29/$D29*$C29,2)) -> 0 | J29: =IF($D29=0,0,ROUND(I29/$D29*$C29,2)) -> 0 | L29: =IF($D29=0,0,ROUND(K29/$D29*$C29,2)) -> 0 | N29: =IF($D29=0,0,ROUND(M29/$D29*$C29,2)) -> 0 | P29: =IF($D29=0,0,ROUND(O29/$D29*$C29,2)) -> 0 | R29: =IF($D29=0,0,ROUND(Q29/$D29*$C29,2)) -> 0 | T29: =IF($D29=0,0,ROUND(S29/$D29*$C29,2)) -> 0 | V29: =IF($D29=0,0,ROUND(U29/$D29*$C29,2)) -> 0 | X29: =IF($D29=0,0,ROUND(W29/$D29*$C29,2)) -> 0 | Z29: =IF($D29=0,0,ROUND(Y29/$D29*$C29,2)) -> 0 | AA29: =D29-E29 -> 0 | AO29: =SUM(AC29:AN29) -> 0
A30: 25 | E30: =G30+I30+K30+M30+O30+Q30+S30+U30+W30+Y30 -> 0 | F30: =H30+J30+L30+N30+P30+R30+T30+V30+X30+Z30 -> 0 | H30: =IF($D30=0,0,ROUND(G30/$D30*$C30,2)) -> 0 | J30: =IF($D30=0,0,ROUND(I30/$D30*$C30,2)) -> 0 | L30: =IF($D30=0,0,ROUND(K30/$D30*$C30,2)) -> 0 | N30: =IF($D30=0,0,ROUND(M30/$D30*$C30,2)) -> 0 | P30: =IF($D30=0,0,ROUND(O30/$D30*$C30,2)) -> 0 | R30: =IF($D30=0,0,ROUND(Q30/$D30*$C30,2)) -> 0 | T30: =IF($D30=0,0,ROUND(S30/$D30*$C30,2)) -> 0 | V30: =IF($D30=0,0,ROUND(U30/$D30*$C30,2)) -> 0 | X30: =IF($D30=0,0,ROUND(W30/$D30*$C30,2)) -> 0 | Z30: =IF($D30=0,0,ROUND(Y30/$D30*$C30,2)) -> 0 | AA30: =D30-E30 -> 0 | AO30: =SUM(AC30:AN30) -> 0
A31: 26 | E31: =G31+I31+K31+M31+O31+Q31+S31+U31+W31+Y31 -> 0 | F31: =H31+J31+L31+N31+P31+R31+T31+V31+X31+Z31 -> 0 | H31: =IF($D31=0,0,ROUND(G31/$D31*$C31,2)) -> 0 | J31: =IF($D31=0,0,ROUND(I31/$D31*$C31,2)) -> 0 | L31: =IF($D31=0,0,ROUND(K31/$D31*$C31,2)) -> 0 | N31: =IF($D31=0,0,ROUND(M31/$D31*$C31,2)) -> 0 | P31: =IF($D31=0,0,ROUND(O31/$D31*$C31,2)) -> 0 | R31: =IF($D31=0,0,ROUND(Q31/$D31*$C31,2)) -> 0 | T31: =IF($D31=0,0,ROUND(S31/$D31*$C31,2)) -> 0 | V31: =IF($D31=0,0,ROUND(U31/$D31*$C31,2)) -> 0 | X31: =IF($D31=0,0,ROUND(W31/$D31*$C31,2)) -> 0 | Z31: =IF($D31=0,0,ROUND(Y31/$D31*$C31,2)) -> 0 | AA31: =D31-E31 -> 0 | AO31: =SUM(AC31:AN31) -> 0
A32: 27 | E32: =G32+I32+K32+M32+O32+Q32+S32+U32+W32+Y32 -> 0 | F32: =H32+J32+L32+N32+P32+R32+T32+V32+X32+Z32 -> 0 | H32: =IF($D32=0,0,ROUND(G32/$D32*$C32,2)) -> 0 | J32: =IF($D32=0,0,ROUND(I32/$D32*$C32,2)) -> 0 | L32: =IF($D32=0,0,ROUND(K32/$D32*$C32,2)) -> 0 | N32: =IF($D32=0,0,ROUND(M32/$D32*$C32,2)) -> 0 | P32: =IF($D32=0,0,ROUND(O32/$D32*$C32,2)) -> 0 | R32: =IF($D32=0,0,ROUND(Q32/$D32*$C32,2)) -> 0 | T32: =IF($D32=0,0,ROUND(S32/$D32*$C32,2)) -> 0 | V32: =IF($D32=0,0,ROUND(U32/$D32*$C32,2)) -> 0 | X32: =IF($D32=0,0,ROUND(W32/$D32*$C32,2)) -> 0 | Z32: =IF($D32=0,0,ROUND(Y32/$D32*$C32,2)) -> 0 | AA32: =D32-E32 -> 0 | AO32: =SUM(AC32:AN32) -> 0
A33: 28 | E33: =G33+I33+K33+M33+O33+Q33+S33+U33+W33+Y33 -> 0 | F33: =H33+J33+L33+N33+P33+R33+T33+V33+X33+Z33 -> 0 | H33: =IF($D33=0,0,ROUND(G33/$D33*$C33,2)) -> 0 | J33: =IF($D33=0,0,ROUND(I33/$D33*$C33,2)) -> 0 | L33: =IF($D33=0,0,ROUND(K33/$D33*$C33,2)) -> 0 | N33: =IF($D33=0,0,ROUND(M33/$D33*$C33,2)) -> 0 | P33: =IF($D33=0,0,ROUND(O33/$D33*$C33,2)) -> 0 | R33: =IF($D33=0,0,ROUND(Q33/$D33*$C33,2)) -> 0 | T33: =IF($D33=0,0,ROUND(S33/$D33*$C33,2)) -> 0 | V33: =IF($D33=0,0,ROUND(U33/$D33*$C33,2)) -> 0 | X33: =IF($D33=0,0,ROUND(W33/$D33*$C33,2)) -> 0 | Z33: =IF($D33=0,0,ROUND(Y33/$D33*$C33,2)) -> 0 | AA33: =D33-E33 -> 0 | AO33: =SUM(AC33:AN33) -> 0
A34: 29 | E34: =G34+I34+K34+M34+O34+Q34+S34+U34+W34+Y34 -> 0 | F34: =H34+J34+L34+N34+P34+R34+T34+V34+X34+Z34 -> 0 | H34: =IF($D34=0,0,ROUND(G34/$D34*$C34,2)) -> 0 | J34: =IF($D34=0,0,ROUND(I34/$D34*$C34,2)) -> 0 | L34: =IF($D34=0,0,ROUND(K34/$D34*$C34,2)) -> 0 | N34: =IF($D34=0,0,ROUND(M34/$D34*$C34,2)) -> 0 | P34: =IF($D34=0,0,ROUND(O34/$D34*$C34,2)) -> 0 | R34: =IF($D34=0,0,ROUND(Q34/$D34*$C34,2)) -> 0 | T34: =IF($D34=0,0,ROUND(S34/$D34*$C34,2)) -> 0 | V34: =IF($D34=0,0,ROUND(U34/$D34*$C34,2)) -> 0 | X34: =IF($D34=0,0,ROUND(W34/$D34*$C34,2)) -> 0 | Z34: =IF($D34=0,0,ROUND(Y34/$D34*$C34,2)) -> 0 | AA34: =D34-E34 -> 0 | AO34: =SUM(AC34:AN34) -> 0
A35: 30 | E35: =G35+I35+K35+M35+O35+Q35+S35+U35+W35+Y35 -> 0 | F35: =H35+J35+L35+N35+P35+R35+T35+V35+X35+Z35 -> 0 | H35: =IF($D35=0,0,ROUND(G35/$D35*$C35,2)) -> 0 | J35: =IF($D35=0,0,ROUND(I35/$D35*$C35,2)) -> 0 | L35: =IF($D35=0,0,ROUND(K35/$D35*$C35,2)) -> 0 | N35: =IF($D35=0,0,ROUND(M35/$D35*$C35,2)) -> 0 | P35: =IF($D35=0,0,ROUND(O35/$D35*$C35,2)) -> 0 | R35: =IF($D35=0,0,ROUND(Q35/$D35*$C35,2)) -> 0 | T35: =IF($D35=0,0,ROUND(S35/$D35*$C35,2)) -> 0 | V35: =IF($D35=0,0,ROUND(U35/$D35*$C35,2)) -> 0 | X35: =IF($D35=0,0,ROUND(W35/$D35*$C35,2)) -> 0 | Z35: =IF($D35=0,0,ROUND(Y35/$D35*$C35,2)) -> 0 | AA35: =D35-E35 -> 0 | AO35: =SUM(AC35:AN35) -> 0
A36: 合计 | C36: =SUM(C6:C35) -> 0 | D36: =SUM(D6:D35) -> 0 | E36: =SUM(E6:E35) -> 0 | F36: =SUM(F6:F35) -> 0 | G36: =SUM(G6:G35) -> 0 | H36: =SUM(H6:H35) -> 0 | I36: =SUM(I6:I35) -> 0 | J36: =SUM(J6:J35) -> 0 | ... Z36: =SUM(Z6:Z35) -> 0 | AB36: 合计 | AC36: =SUM(AC6:AC35) -> 0
B38: 2025年2月份研发人员工资项目分摊表
A40: 序号 | B40: 姓名 | C40: 月工资 | D40: 出勤天数 | E40: 研发天数合计 | F40: 研发工资合计 | G40: =立项!$A$3 -> RD01 | I40: =立项!$A$4 -> RD02 | K40: =立项!$A$5 -> RD03 | M40: =立项!$A$6 -> RD04 | O40: =立项!$A$7 -> RD05 | Q40: =立项!$A$8 -> RD06 | S40: =立项!$A$9 -> RD07 | U40: =立项!$A$10 -> RD08 | W40: =立项!$A$11 -> RD09 | Y40: =立项!$A$12 -> RD10
G41: =立项!C3 -> 0 | I41: =立项!C4 -> 0 | K41: =立项!C5 -> 0 | M41: =立项!C6 -> 0 | O41: =立项!C7 -> 0 | Q41: =立项!C8 -> 0 | S41: =立项!C9 -> 0 | U41: =立项!C10 -> 0 | W41: =立项!C11 -> 0 | Y41: =立项!C12 -> 0
G42: 研发天数 | H42: 研发工资 | I42: 研发天数 | J42: 研发工资 | K42: 研发天数 | L42: 研发工资 | M42: 研发天数 | N42: 研发工资 | O42: 研发天数 | P42: 研发工资 | Q42: 研发天数 | R42: 研发工资 | S42: 研发天数 | T42: 研发工资 | U42: 研发天数 | V42: 研发工资 | W42: 研发天数 | X42: 研发工资 | Y42: 研发天数 | Z42: 研发工资
A43: 1 | E43: =G43+I43+K43+M43+O43+Q43+S43+U43+W43+Y43 -> 0 | F43: =H43+J43+L43+N43+P43+R43+T43+V43+X43+Z43 -> 0 | H43: =IF($D43=0,0,ROUND(G43/$D43*$C43,2)) -> 0 | J43: =IF($D43=0,0,ROUND(I43/$D43*$C43,2)) -> 0 | L43: =IF($D43=0,0,ROUND(K43/$D43*$C43,2)) -> 0 | N43: =IF($D43=0,0,ROUND(M43/$D43*$C43,2)) -> 0 | P43: =IF($D43=0,0,ROUND(O43/$D43*$C43,2)) -> 0 | R43: =IF($D43=0,0,ROUND(Q43/$D43*$C43,2)) -> 0 | T43: =IF($D43=0,0,ROUND(S43/$D43*$C43,2)) -> 0 | V43: =IF($D43=0,0,ROUND(U43/$D43*$C43,2)) -> 0 | X43: =IF($D43=0,0,ROUND(W43/$D43*$C43,2)) -> 0 | Z43: =IF($D43=0,0,ROUND(Y43/$D43*$C43,2)) -> 0 | AA43: =D43-E43 -> 0
A44: 2 | E44: =G44+I44+K44+M44+O44+Q44+S44+U44+W44+Y44 -> 0 | F44: =H44+J44+L44+N44+P44+R44+T44+V44+X44+Z44 -> 0 | H44: =IF($D44=0,0,ROUND(G44/$D44*$C44,2)) -> 0 | J44: =IF($D44=0,0,ROUND(I44/$D44*$C44,2)) -> 0 | L44: =IF($D44=0,0,ROUND(K44/$D44*$C44,2)) -> 0 | N44: =IF($D44=0,0,ROUND(M44/$D44*$C44,2)) -> 0 | P44: =IF($D44=0,0,ROUND(O44/$D44*$C44,2)) -> 0 | R44: =IF($D44=0,0,ROUND(Q44/$D44*$C44,2)) -> 0 | T44: =IF($D44=0,0,ROUND(S44/$D44*$C44,2)) -> 0 | V44: =IF($D44=0,0,ROUND(U44/$D44*$C44,2)) -> 0 | X44: =IF($D44=0,0,ROUND(W44/$D44*$C44,2)) -> 0 | Z44: =IF($D44=0,0,ROUND(Y44/$D44*$C44,2)) -> 0 | AA44: =D44-E44 -> 0
A45: 3 | E45: =G45+I45+K45+M45+O45+Q45+S45+U45+W45+Y45 -> 0 | F45: =H45+J45+L45+N45+P45+R45+T45+V45+X45+Z45 -> 0 | H45: =IF($D45=0,0,ROUND(G45/$D45*$C45,2)) -> 0 | J45: =IF($D45=0,0,ROUND(I45/$D45*$C45,2)) -> 0 | L45: =IF($D45=0,0,ROUND(K45/$D45*$C45,2)) -> 0 | N45: =IF($D45=0,0,ROUND(M45/$D45*$C45,2)) -> 0 | P45: =IF($D45=0,0,ROUND(O45/$D45*$C45,2)) -> 0 | R45: =IF($D45=0,0,ROUND(Q45/$D45*$C45,2)) -> 0 | T45: =IF($D45=0,0,ROUND(S45/$D45*$C45,2)) -> 0 | V45: =IF($D45=0,0,ROUND(U45/$D45*$C45,2)) -> 0 | X45: =IF($D45=0,0,ROUND(W45/$D45*$C45,2)) -> 0 | Z45: =IF($D45=0,0,ROUND(Y45/$D45*$C45,2)) -> 0 | AA45: =D45-E45 -> 0
A46: 4 | E46: =G46+I46+K46+M46+O46+Q46+S46+U46+W46+Y46 -> 0 | F46: =H46+J46+L46+N46+P46+R46+T46+V46+X46+Z46 -> 0 | H46: =IF($D46=0,0,ROUND(G46/$D46*$C46,2)) -> 0 | J46: =IF($D46=0,0,ROUND(I46/$D46*$C46,2)) -> 0 | L46: =IF($D46=0,0,ROUND(K46/$D46*$C46,2)) -> 0 | N46: =IF($D46=0,0,ROUND(M46/$D46*$C46,2)) -> 0 | P46: =IF($D46=0,0,ROUND(O46/$D46*$C46,2)) -> 0 | R46: =IF($D46=0,0,ROUND(Q46/$D46*$C46,2)) -> 0 | T46: =IF($D46=0,0,ROUND(S46/$D46*$C46,2)) -> 0 | V46: =IF($D46=0,0,ROUND(U46/$D46*$C46,2)) -> 0 | X46: =IF($D46=0,0,ROUND(W46/$D46*$C46,2)) -> 0 | Z46: =IF($D46=0,0,ROUND(Y46/$D46*$C46,2)) -> 0 | AA46: =D46-E46 -> 0
A47: 5 | E47: =G47+I47+K47+M47+O47+Q47+S47+U47+W47+Y47 -> 0 | F47: =H47+J47+L47+N47+P47+R47+T47+V47+X47+Z47 -> 0 | H47: =IF($D47=0,0,ROUND(G47/$D47*$C47,2)) -> 0 | J47: =IF($D47=0,0,ROUND(I47/$D47*$C47,2)) -> 0 | L47: =IF($D47=0,0,ROUND(K47/$D47*$C47,2)) -> 0 | N47: =IF($D47=0,0,ROUND(M47/$D47*$C47,2)) -> 0 | P47: =IF($D47=0,0,ROUND(O47/$D47*$C47,2)) -> 0 | R47: =IF($D47=0,0,ROUND(Q47/$D47*$C47,2)) -> 0 | T47: =IF($D47=0,0,ROUND(S47/$D47*$C47,2)) -> 0 | V47: =IF($D47=0,0,ROUND(U47/$D47*$C47,2)) -> 0 | X47: =IF($D47=0,0,ROUND(W47/$D47*$C47,2)) -> 0 | Z47: =IF($D47=0,0,ROUND(Y47/$D47*$C47,2)) -> 0 | AA47: =D47-E47 -> 0
A48: 6 | E48: =G48+I48+K48+M48+O48+Q48+S48+U48+W48+Y48 -> 0 | F48: =H48+J48+L48+N48+P48+R48+T48+V48+X48+Z48 -> 0 | H48: =IF($D48=0,0,ROUND(G48/$D48*$C48,2)) -> 0 | J48: =IF($D48=0,0,ROUND(I48/$D48*$C48,2)) -> 0 | L48: =IF($D48=0,0,ROUND(K48/$D48*$C48,2)) -> 0 | N48: =IF($D48=0,0,ROUND(M48/$D48*$C48,2)) -> 0 | P48: =IF($D48=0,0,ROUND(O48/$D48*$C48,2)) -> 0 | R48: =IF($D48=0,0,ROUND(Q48/$D48*$C48,2)) -> 0 | T48: =IF($D48=0,0,ROUND(S48/$D48*$C48,2)) -> 0 | V48: =IF($D48=0,0,ROUND(U48/$D48*$C48,2)) -> 0 | X48: =IF($D48=0,0,ROUND(W48/$D48*$C48,2)) -> 0 | Z48: =IF($D48=0,0,ROUND(Y48/$D48*$C48,2)) -> 0 | AA48: =D48-E48 -> 0
...

Sheet 研发人员考勤表
A1: 研发人员考勤表
A2: 45658
A3: 姓名 | B3: 项目名称 | C3: 1日 | D3: 2日 | E3: 3日 | F3: 4日 | G3: 5日 | H3: 6日 | I3: 7日 | J3: 8日 | K3: 9日 | L3: 10日 | M3: 11日 | N3: 12日 | O3: 13日 | P3: 14日 | Q3: 15日 | R3: 16日 | S3: 17日 | T3: 18日 | U3: 19日 | V3: 20日 | W3: 21日 | X3: 22日 | Y3: 23日 | Z3: 25日 | AA3: 25日 | AB3: 26日 | AC3: 27日 | AD3: 28日 | AE3: 29日 | AF3: 30日 | AG3: 31日 | AH3: 合计 | AI3: 22
B4: RD01 | D4: √ | E4: √ | J4: √ | K4: √ | L4: √ | Q4: √ | R4: √ | S4: √ | X4: √ | Y4: √ | Z4: √ | AE4: √ | AF4: √ | AG4: √ | AH4: =COUNTIF(C4:AG4,"√") -> 14
B5: RD02 | F5: √ | G5: √ | H5: √ | M5: √ | N5: √ | O5: √ | T5: √ | U5: √ | V5: √ | AA5: √ | AB5: √ | AC5: √ | AH5: =COUNTIF(C5:AG5,"√") -> 12
B6: RD03 | AH6: =COUNTIF(C6:AG6,"√") -> 0
B7: RD04 | AH7: =COUNTIF(C7:AG7,"√") -> 0
B8: RD05 | AH8: =COUNTIF(C8:AG8,"√") -> 0
B9: RD01 | D9: √ | E9: √ | F9: √ | G9: √ | H9: √ | J9: √ | K9: √ | L9: √ | M9: √ | N9: √ | O9: √ | Q9: √ | R9: √ | S9: √ | T9: √ | U9: √ | V9: √ | X9: √ | Y9: √ | Z9: √ | AA9: √ | AB9: √ | AC9: √ | AE9: √ | AF9: √ | AG9: √ | AH9: =COUNTIF(C9:AG9,"√") -> 26
B10: RD02 | AH10: =COUNTIF(C10:AG10,"√") -> 0
B11: RD03 | AH11: =COUNTIF(C11:AG11,"√") -> 0
B12: RD04 | AH12: =COUNTIF(C12:AG12,"√") -> 0
B13: RD05 | AH13: =COUNTIF(C13:AG13,"√") -> 0
B14: RD01 | AH14: =COUNTIF(C14:AG14,"√") -> 0
B15: RD02 | AH15: =COUNTIF(C15:AG15,"√") -> 0
B16: RD03 | AH16: =COUNTIF(C16:AG16,"√") -> 0
B17: RD04 | AH17: =COUNTIF(C17:AG17,"√") -> 0
B18: RD05 | AH18: =COUNTIF(C18:AG18,"√") -> 0
B19: RD01 | AH19: =COUNTIF(C19:AG19,"√") -> 0
B20: RD02 | AH20: =COUNTIF(C20:AG20,"√") -> 0
B21: RD03 | AH21: =COUNTIF(C21:AG21,"√") -> 0
... B23: RD05 | AH23: =COUNTIF(C23:AG23,"√") -> 0
A24: 制表： 审核： 人事主管：
A27: 研发人员考勤表
A28: 45689
A29: 姓名 | B29: 项目名称 | C29: 1日 | D29: 2日 | E29: 3日 | F29: 4日 | G29: 5日 | H29: 6日 | I29: 7日 | J29: 8日 | K29: 9日 | L29: 10日 | M29: 11日 | N29: 12日 | O29: 13日 | P29: 14日 | Q29: 15日 | R29: 16日 | S29: 17日 | T29: 18日 | U29: 19日 | V29: 20日 | W29: 21日 | X29: 22日 | Y29: 23日 | Z29: 25日 | AA29: 25日 | AB29: 26日 | AC29: 27日 | AD29: 28日 | AF29: 合计 | AI29: 18
B30: RD01 | C30: √ | D30: √ | I30: √ | J30: √ | K30: √ | V30: √ | W30: √ | AB30: √ | AC30: √ | AF30: =COUNTIF(C30:AE30,"√") -> 9
B31: RD02 | F31: √ | G31: √ | H31: √ | T31: √ | U31: √ | X31: √ | Y31: √ | Z31: √ | AD31: √ | AF31: =COUNTIF(C31:AE31,"√") -> 9
B32: RD03 | AF32: =COUNTIF(C32:AE32,"√") -> 0
B33: RD04 | AF33: =COUNTIF(C33:AE33,"√") -> 0
B34: RD05 | AF34: =COUNTIF(C34:AE34,"√") -> 0
B35: RD01 | C35: √ | D35: √ | F35: √ | G35: √ | H35: √ | I35: √ | J35: √ | K35: √ | T35: √ | U35: √ | V35: √ | W35: √ | X35: √ | Y35: √ | Z35: √ | AB35: √ | AC35: √ | AD35: √ | AF35: =COUNTIF(C35:AE35,"√") -> 18
B36: RD02 | AF36: =COUNTIF(C36:AE36,"√") -> 0
B37: RD03 | AF37: =COUNTIF(C37:AE37,"√") -> 0
B38: RD04 | AF38: =COUNTIF(C38:AE38,"√") -> 0
B39: RD05 | AF39: =COUNTIF(C39:AE39,"√") -> 0
B40: RD01 | AF40: =COUNTIF(C40:AE40,"√") -> 0
B41: RD02 | AF41: =COUNTIF(C41:AE41,"√") -> 0
B42: RD03 | AF42: =COUNTIF(C42:AE42,"√") -> 0
B43: RD04 | AF43: =COUNTIF(C43:AE43,"√") -> 0
...

Sheet 研发人员出勤考勤表
A2: 2023年1月份研发人员考勤表
A4: 姓名 | B4: 星期日 | C4: 星期一 | D4: 星期二 | E4: 星期三 | F4: 星期四 | G4: 星期五 | H4: 星期六 | I4: 星期日 | J4: 星期一 | K4: 星期二 | L4: 星期三 | M4: 星期四 | N4: 星期五 | O4: 星期六 | P4: 星期日 | Q4: 星期一 | R4: 星期二 | S4: 星期三 | T4: 星期四 | U4: 星期五 | V4: 星期六 | W4: 星期日 | X4: 星期一 | Y4: 星期二 | Z4: 星期三 | AA4: 星期四 | AB4: 星期五 | AC4: 星期六 | AD4: 星期日 | AE4: 星期一 | AF4: 星期二 | AG4: 研发天数 | AH4: 出勤天数 | AI4: 研发天数验证 | AJ4: 出勤天数验证
B5: 1 | C5: 2 | D5: 3 | E5: 4 | F5: 5 | G5: 6 | H5: 7 | I5: 8 | J5: 9 | K5: 10 | L5: 11 | M5: 12 | N5: 13 | O5: 14 | P5: 15 | Q5: 16 | R5: 17 | S5: 18 | T5: 19 | U5: 20 | V5: 21 | W5: 22 | X5: 23 | Y5: 24 | Z5: 25 | AA5: 26 | AB5: 27 | AC5: 28 | AD5: 29 | AE5: 30 | AF5: 31
A6: ='人员人工-研发人员工资'!B6 -> 0 | B6: × | C6: × | D6: ● | E6: ● | F6: ● | G6: √ | H6: × | I6: × | J6: ● | K6: ● | L6: ● | M6: ● | N6: √ | O6: × | P6: × | Q6: ▲ | R6: ▲ | S6: ▲ | T6: ▲ | U6: ▲ | V6: × | W6: × | X6: × | Y6: × | Z6: × | AA6: × | AB6: × | AC6: ■ | AD6: ■ | AE6: ■ | AF6: ■ | AG6: =COUNTIF(B6:AF6,"●")+COUNTIF(B6:AF6,"▲")+COUNTIF(B6:AF6,"■")+COUNTIF(B6:AF6,"★")+COUNTIF(B6:AF6,"◆")+COUNTIF(B6:AF6,"✽")+COUNTIF(B6:AF6,"❖")+COUNTIF(B6:AF6,"✪")+COUNTIF(B6:AF6,"✿")+COUNTIF(B6:AF6,"✤") -> 16 | AH6: =COUNTIF(B6:AF6,"●")+COUNTIF(B6:AF6,"▲")+COUNTIF(B6:AF6,"■")+COUNTIF(B6:AF6,"★")+COUNTIF(B6:AF6,"◆")+COUNTIF(B6:AF6,"✽")+COUNTIF(B6:AF6,"❖")+COUNTIF(B6:AF6,"✪")+COUNTIF(B6:AF6,"✿")+COUNTIF(B6:AF6,"✤")+COUNTIF(B6:AF6,"√") -> 18 | AI6: =AG6-'人员人工-研发人员工资'!E6 -> 16 | AJ6: =AH6-'人员人工-研发人员工资'!D6 -> 18
A7: ='人员人工-研发人员工资'!B7 -> 0 | AG7: =COUNTIF(B7:AF7,"●")+COUNTIF(B7:AF7,"▲")+COUNTIF(B7:AF7,"■")+COUNTIF(B7:AF7,"★")+COUNTIF(B7:AF7,"◆")+COUNTIF(B7:AF7,"✽")+COUNTIF(B7:AF7,"❖")+COUNTIF(B7:AF7,"✪")+COUNTIF(B7:AF7,"✿")+COUNTIF(B7:AF7,"✤") -> 0 | AH7: =COUNTIF(B7:AF7,"●")+COUNTIF(B7:AF7,"▲")+COUNTIF(B7:AF7,"■")+COUNTIF(B7:AF7,"★")+COUNTIF(B7:AF7,"◆")+COUNTIF(B7:AF7,"✽")+COUNTIF(B7:AF7,"❖")+COUNTIF(B7:AF7,"✪")+COUNTIF(B7:AF7,"✿")+COUNTIF(B7:AF7,"✤")+COUNTIF(B7:AF7,"√") -> 0 | AI7: =AG7-'人员人工-研发人员工资'!E7 -> 0 | AJ7: =AH7-'人员人工-研发人员工资'!D7 -> 0
A8: ='人员人工-研发人员工资'!B8 -> 0 | AG8: =COUNTIF(B8:AF8,"●")+COUNTIF(B8:AF8,"▲")+COUNTIF(B8:AF8,"■")+COUNTIF(B8:AF8,"★")+COUNTIF(B8:AF8,"◆")+COUNTIF(B8:AF8,"✽")+COUNTIF(B8:AF8,"❖")+COUNTIF(B8:AF8,"✪")+COUNTIF(B8:AF8,"✿")+COUNTIF(B8:AF8,"✤") -> 0 | AH8: =COUNTIF(B8:AF8,"●")+COUNTIF(B8:AF8,"▲")+COUNTIF(B8:AF8,"■")+COUNTIF(B8:AF8,"★")+COUNTIF(B8:AF8,"◆")+COUNTIF(B8:AF8,"✽")+COUNTIF(B8:AF8,"❖")+COUNTIF(B8:AF8,"✪")+COUNTIF(B8:AF8,"✿")+COUNTIF(B8:AF8,"✤")+COUNTIF(B8:AF8,"√") -> 0 | AI8: =AG8-'人员人工-研发人员工资'!E8 -> 0 | AJ8: =AH8-'人员人工-研发人员工资'!D8 -> 0
A9: ='人员人工-研发人员工资'!B9 -> 0 | AG9: =COUNTIF(B9:AF9,"●")+COUNTIF(B9:AF9,"▲")+COUNTIF(B9:AF9,"■")+COUNTIF(B9:AF9,"★")+COUNTIF(B9:AF9,"◆")+COUNTIF(B9:AF9,"✽")+COUNTIF(B9:AF9,"❖")+COUNTIF(B9:AF9,"✪")+COUNTIF(B9:AF9,"✿")+COUNTIF(B9:AF9,"✤") -> 0 | AH9: =COUNTIF(B9:AF9,"●")+COUNTIF(B9:AF9,"▲")+COUNTIF(B9:AF9,"■")+COUNTIF(B9:AF9,"★")+COUNTIF(B9:AF9,"◆")+COUNTIF(B9:AF9,"✽")+COUNTIF(B9:AF9,"❖")+COUNTIF(B9:AF9,"✪")+COUNTIF(B9:AF9,"✿")+COUNTIF(B9:AF9,"✤")+COUNTIF(B9:AF9,"√") -> 0 | AI9: =AG9-'人员人工-研发人员工资'!E9 -> 0 | AJ9: =AH9-'人员人工-研发人员工资'!D9 -> 0
A10: ='人员人工-研发人员工资'!B10 -> 0 | AG10: =COUNTIF(B10:AF10,"●")+COUNTIF(B10:AF10,"▲")+COUNTIF(B10:AF10,"■")+COUNTIF(B10:AF10,"★")+COUNTIF(B10:AF10,"◆")+COUNTIF(B10:AF10,"✽")+COUNTIF(B10:AF10,"❖")+COUNTIF(B10:AF10,"✪")+COUNTIF(B10:AF10,"✿")+COUNTIF(B10:AF10,"✤") -> 0 | AH10: =COUNTIF(B10:AF10,"●")+COUNTIF(B10:AF10,"▲")+COUNTIF(B10:AF10,"■")+COUNTIF(B10:AF10,"★")+COUNTIF(B10:AF10,"◆")+COUNTIF(B10:AF10,"✽")+COUNTIF(B10:AF10,"❖")+COUNTIF(B10:AF10,"✪")+COUNTIF(B10:AF10,"✿")+COUNTIF(B10:AF10,"✤")+COUNTIF(B10:AF10,"√") -> 0 | AI10: =AG10-'人员人工-研发人员工资'!E10 -> 0 | AJ10: =AH10-'人员人工-研发人员工资'!D10 -> 0
A11: ='人员人工-研发人员工资'!B11 -> 0 | AG11: =COUNTIF(B11:AF11,"●")+COUNTIF(B11:AF11,"▲")+COUNTIF(B11:AF11,"■")+COUNTIF(B11:AF11,"★")+COUNTIF(B11:AF11,"◆")+COUNTIF(B11:AF11,"✽")+COUNTIF(B11:AF11,"❖")+COUNTIF(B11:AF11,"✪")+COUNTIF(B11:AF11,"✿")+COUNTIF(B11:AF11,"✤") -> 0 | AH11: =COUNTIF(B11:AF11,"●")+COUNTIF(B11:AF11,"▲")+COUNTIF(B11:AF11,"■")+COUNTIF(B11:AF11,"★")+COUNTIF(B11:AF11,"◆")+COUNTIF(B11:AF11,"✽")+COUNTIF(B11:AF11,"❖")+COUNTIF(B11:AF11,"✪")+COUNTIF(B11:AF11,"✿")+COUNTIF(B11:AF11,"✤")+COUNTIF(B11:AF11,"√") -> 0 | AI11: =AG11-'人员人工-研发人员工资'!E11 -> 0 | AJ11: =AH11-'人员人工-研发人员工资'!D11 -> 0
A12: ='人员人工-研发人员工资'!B12 -> 0 | AG12: =COUNTIF(B12:AF12,"●")+COUNTIF(B12:AF12,"▲")+COUNTIF(B12:AF12,"■")+COUNTIF(B12:AF12,"★")+COUNTIF(B12:AF12,"◆")+COUNTIF(B12:AF12,"✽")+COUNTIF(B12:AF12,"❖")+COUNTIF(B12:AF12,"✪")+COUNTIF(B12:AF12,"✿")+COUNTIF(B12:AF12,"✤") -> 0 | AH12: =COUNTIF(B12:AF12,"●")+COUNTIF(B12:AF12,"▲")+COUNTIF(B12:AF12,"■")+COUNTIF(B12:AF12,"★")+COUNTIF(B12:AF12,"◆")+COUNTIF(B12:AF12,"✽")+COUNTIF(B12:AF12,"❖")+COUNTIF(B12:AF12,"✪")+COUNTIF(B12:AF12,"✿")+COUNTIF(B12:AF12,"✤")+COUNTIF(B12:AF12,"√") -> 0 | AI12: =AG12-'人员人工-研发人员工资'!E12 -> 0 | AJ12: =AH12-'人员人工-研发人员工资'!D12 -> 0
A13: ='人员人工-研发人员工资'!B13 -> 0 | AG13: =COUNTIF(B13:AF13,"●")+COUNTIF(B13:AF13,"▲")+COUNTIF(B13:AF13,"■")+COUNTIF(B13:AF13,"★")+COUNTIF(B13:AF13,"◆")+COUNTIF(B13:AF13,"✽")+COUNTIF(B13:AF13,"❖")+COUNTIF(B13:AF13,"✪")+COUNTIF(B13:AF13,"✿")+COUNTIF(B13:AF13,"✤") -> 0 | AH13: =COUNTIF(B13:AF13,"●")+COUNTIF(B13:AF13,"▲")+COUNTIF(B13:AF13,"■")+COUNTIF(B13:AF13,"★")+COUNTIF(B13:AF13,"◆")+COUNTIF(B13:AF13,"✽")+COUNTIF(B13:AF13,"❖")+COUNTIF(B13:AF13,"✪")+COUNTIF(B13:AF13,"✿")+COUNTIF(B13:AF13,"✤")+COUNTIF(B13:AF13,"√") -> 0 | AI13: =AG13-'人员人工-研发人员工资'!E13 -> 0 | AJ13: =AH13-'人员人工-研发人员工资'!D13 -> 0
A14: ='人员人工-研发人员工资'!B14 -> 0 | AG14: =COUNTIF(B14:AF14,"●")+COUNTIF(B14:AF14,"▲")+COUNTIF(B14:AF14,"■")+COUNTIF(B14:AF14,"★")+COUNTIF(B14:AF14,"◆")+COUNTIF(B14:AF14,"✽")+COUNTIF(B14:AF14,"❖")+COUNTIF(B14:AF14,"✪")+COUNTIF(B14:AF14,"✿")+COUNTIF(B14:AF14,"✤") -> 0 | AH14: =COUNTIF(B14:AF14,"●")+COUNTIF(B14:AF14,"▲")+COUNTIF(B14:AF14,"■")+COUNTIF(B14:AF14,"★")+COUNTIF(B14:AF14,"◆")+COUNTIF(B14:AF14,"✽")+COUNTIF(B14:AF14,"❖")+COUNTIF(B14:AF14,"✪")+COUNTIF(B14:AF14,"✿")+COUNTIF(B14:AF14,"✤")+COUNTIF(B14:AF14,"√") -> 0 | AI14: =AG14-'人员人工-研发人员工资'!E14 -> 0 | AJ14: =AH14-'人员人工-研发人员工资'!D14 -> 0
A15: ='人员人工-研发人员工资'!B15 -> 0 | AG15: =COUNTIF(B15:AF15,"●")+COUNTIF(B15:AF15,"▲")+COUNTIF(B15:AF15,"■")+COUNTIF(B15:AF15,"★")+COUNTIF(B15:AF15,"◆")+COUNTIF(B15:AF15,"✽")+COUNTIF(B15:AF15,"❖")+COUNTIF(B15:AF15,"✪")+COUNTIF(B15:AF15,"✿")+COUNTIF(B15:AF15,"✤") -> 0 | AH15: =COUNTIF(B15:AF15,"●")+COUNTIF(B15:AF15,"▲")+COUNTIF(B15:AF15,"■")+COUNTIF(B15:AF15,"★")+COUNTIF(B15:AF15,"◆")+COUNTIF(B15:AF15,"✽")+COUNTIF(B15:AF15,"❖")+COUNTIF(B15:AF15,"✪")+COUNTIF(B15:AF15,"✿")+COUNTIF(B15:AF15,"✤")+COUNTIF(B15:AF15,"√") -> 0 | AI15: =AG15-'人员人工-研发人员工资'!E15 -> 0 | AJ15: =AH15-'人员人工-研发人员工资'!D15 -> 0
A16: ='人员人工-研发人员工资'!B16 -> 0 | AG16: =COUNTIF(B16:AF16,"●")+COUNTIF(B16:AF16,"▲")+COUNTIF(B16:AF16,"■")+COUNTIF(B16:AF16,"★")+COUNTIF(B16:AF16,"◆")+COUNTIF(B16:AF16,"✽")+COUNTIF(B16:AF16,"❖")+COUNTIF(B16:AF16,"✪")+COUNTIF(B16:AF16,"✿")+COUNTIF(B16:AF16,"✤") -> 0 | AH16: =COUNTIF(B16:AF16,"●")+COUNTIF(B16:AF16,"▲")+COUNTIF(B16:AF16,"■")+COUNTIF(B16:AF16,"★")+COUNTIF(B16:AF16,"◆")+COUNTIF(B16:AF16,"✽")+COUNTIF(B16:AF16,"❖")+COUNTIF(B16:AF16,"✪")+COUNTIF(B16:AF16,"✿")+COUNTIF(B16:AF16,"✤")+COUNTIF(B16:AF16,"√") -> 0 | AI16: =AG16-'人员人工-研发人员工资'!E16 -> 0 | AJ16: =AH16-'人员人工-研发人员工资'!D16 -> 0
A17: ='人员人工-研发人员工资'!B17 -> 0 | AG17: =COUNTIF(B17:AF17,"●")+COUNTIF(B17:AF17,"▲")+COUNTIF(B17:AF17,"■")+COUNTIF(B17:AF17,"★")+COUNTIF(B17:AF17,"◆")+COUNTIF(B17:AF17,"✽")+COUNTIF(B17:AF17,"❖")+COUNTIF(B17:AF17,"✪")+COUNTIF(B17:AF17,"✿")+COUNTIF(B17:AF17,"✤") -> 0 | AH17: =COUNTIF(B17:AF17,"●")+COUNTIF(B17:AF17,"▲")+COUNTIF(B17:AF17,"■")+COUNTIF(B17:AF17,"★")+COUNTIF(B17:AF17,"◆")+COUNTIF(B17:AF17,"✽")+COUNTIF(B17:AF17,"❖")+COUNTIF(B17:AF17,"✪")+COUNTIF(B17:AF17,"✿")+COUNTIF(B17:AF17,"✤")+COUNTIF(B17:AF17,"√") -> 0 | AI17: =AG17-'人员人工-研发人员工资'!E17 -> 0 | AJ17: =AH17-'人员人工-研发人员工资'!D17 -> 0
A18: ='人员人工-研发人员工资'!B18 -> 0 | AG18: =COUNTIF(B18:AF18,"●")+COUNTIF(B18:AF18,"▲")+COUNTIF(B18:AF18,"■")+COUNTIF(B18:AF18,"★")+COUNTIF(B18:AF18,"◆")+COUNTIF(B18:AF18,"✽")+COUNTIF(B18:AF18,"❖")+COUNTIF(B18:AF18,"✪")+COUNTIF(B18:AF18,"✿")+COUNTIF(B18:AF18,"✤") -> 0 | AH18: =COUNTIF(B18:AF18,"●")+COUNTIF(B18:AF18,"▲")+COUNTIF(B18:AF18,"■")+COUNTIF(B18:AF18,"★")+COUNTIF(B18:AF18,"◆")+COUNTIF(B18:AF18,"✽")+COUNTIF(B18:AF18,"❖")+COUNTIF(B18:AF18,"✪")+COUNTIF(B18:AF18,"✿")+COUNTIF(B18:AF18,"✤")+COUNTIF(B18:AF18,"√") -> 0 | AI18: =AG18-'人员人工-研发人员工资'!E18 -> 0 | AJ18: =AH18-'人员人工-研发人员工资'!D18 -> 0
... A35: ='人员人工-研发人员工资'!B35 -> 0 | AG35: =COUNTIF(B35:AF35,"●")+COUNTIF(B35:AF35,"▲")+COUNTIF(B35:AF35,"■")+COUNTIF(B35:AF35,"★")+COUNTIF(B35:AF35,"◆")+COUNTIF(B35:AF35,"✽")+COUNTIF(B35:AF35,"❖")+COUNTIF(B35:AF35,"✪")+COUNTIF(B35:AF35,"✿")+COUNTIF(B35:AF35,"✤") -> 0 | AH35: =COUNTIF(B35:AF35,"●")+COUNTIF(B35:AF35,"▲")+COUNTIF(B35:AF35,"■")+COUNTIF(B35:AF35,"★")+COUNTIF(B35:AF35,"◆")+COUNTIF(B35:AF35,"✽")+COUNTIF(B35:AF35,"❖")+COUNTIF(B35:AF35,"✪")+COUNTIF(B35:AF35,"✿")+COUNTIF(B35:AF35,"✤")+COUNTIF(B35:AF35,"√") -> 0 | AI35: =AG35-'人员人工-研发人员工资'!E35 -> 0 | AJ35: =AH35-'人员人工-研发人员工资'!D35 -> 0
A36: 注： | B36: ● | C36: ▲ | D36: ■ | E36: ★ | F36: ◆ | G36: ✽ | H36: ❖ | I36: ✪ | J36: ✿ | K36: ✤ | L36: √ | M36: ×
B37: 1 | C37: 2 | D37: 3 | E37: 4 | F37: 5 | G37: 6 | H37: 7 | I37: 8 | J37: 9 | K37: 10 | L37: 其他出勤 | M37: 未出勤
A39: 2023年2月份研发人员考勤表
A41: 姓名 | B41: 星期三 | C41: 星期四 | D41: 星期五 | E41: 星期六 | F41: 星期日 | G41: 星期一 | H41: 星期二 | I41: 星期三 | J41: 星期四 | K41: 星期五 | L41: 星期六 | M41: 星期日 | N41: 星期一 | O41: 星期二 | P41: 星期三 | Q41: 星期四 | R41: 星期五 | S41: 星期六 | T41: 星期日 | U41: 星期一 | V41: 星期二 | W41: 星期三 | X41: 星期四 | Y41: 星期五 | Z41: 星期六 | AA41: 星期日 | AB41: 星期一 | AC41: 星期二 | AG41: 研发天数 | AH41: 出勤天数 | AI41: 研发天数验证 | AJ41: 出勤天数验证
B42: 1 | C42: 2 | D42: 3 | E42: 4 | F42: 5 | G42: 6 | H42: 7 | I42: 8 | J42: 9 | K42: 10 | L42: 11 | M42: 12 | N42: 13 | O42: 14 | P42: 15 | Q42: 16 | R42: 17 | S42: 18 | T42: 19 | U42: 20 | V42: 21 | W42: 22 | X42: 23 | Y42: 24 | Z42: 25 | AA42: 26 | AB42: 27 | AC42: 28
A43: ='人员人工-研发人员工资'!B43 -> 0 | B43: ● | C43: ● | D43: ● | E43: × | F43: × | G43: ● | H43: ● | I43: √ | J43: ▲ | K43: ▲ | L43: × | M43: × | N43: ▲ | O43: ▲ | P43: ▲ | Q43: √ | R43: √ | S43: × | T43: × | U43: ■ | V43: ■ | W43: ■ | X43: ■ | Y43: ■ | Z43: × | AA43: × | AB43: √ | AC43: √ | AG43: =COUNTIF(B43:AF43,"●")+COUNTIF(B43:AF43,"▲")+COUNTIF(B43:AF43,"■")+COUNTIF(B43:AF43,"★")+COUNTIF(B43:AF43,"◆")+COUNTIF(B43:AF43,"✽")+COUNTIF(B43:AF43,"❖")+COUNTIF(B43:AF43,"✪")+COUNTIF(B43:AF43,"✿")+COUNTIF(B43:AF43,"✤") -> 15 | AH43: =COUNTIF(B43:AF43,"●")+COUNTIF(B43:AF43,"▲")+COUNTIF(B43:AF43,"■")+COUNTIF(B43:AF43,"★")+COUNTIF(B43:AF43,"◆")+COUNTIF(B43:AF43,"✽")+COUNTIF(B43:AF43,"❖")+COUNTIF(B43:AF43,"✪")+COUNTIF(B43:AF43,"✿")+COUNTIF(B43:AF43,"✤")+COUNTIF(B43:AF43,"√") -> 20 | AI43: =AG43-'人员人工-研发人员工资'!E43 -> 15 | AJ43: =AH43-'人员人工-研发人员工资'!D43 -> 20
A44: ='人员人工-研发人员工资'!B44 -> 0 | AG44: =COUNTIF(B44:AF44,"●")+COUNTIF(B44:AF44,"▲")+COUNTIF(B44:AF44,"■")+COUNTIF(B44:AF44,"★")+COUNTIF(B44:AF44,"◆")+COUNTIF(B44:AF44,"✽")+COUNTIF(B44:AF44,"❖")+COUNTIF(B44:AF44,"✪")+COUNTIF(B44:AF44,"✿")+COUNTIF(B44:AF44,"✤") -> 0 | AH44: =COUNTIF(B44:AF44,"●")+COUNTIF(B44:AF44,"▲")+COUNTIF(B44:AF44,"■")+COUNTIF(B44:AF44,"★")+COUNTIF(B44:AF44,"◆")+COUNTIF(B44:AF44,"✽")+COUNTIF(B44:AF44,"❖")+COUNTIF(B44:AF44,"✪")+COUNTIF(B44:AF44,"✿")+COUNTIF(B44:AF44,"✤")+COUNTIF(B44:AF44,"√") -> 0 | AI44: =AG44-'人员人工-研发人员工资'!E44 -> 0 | AJ44: =AH44-'人员人工-研发人员工资'!D44 -> 0
A45: ='人员人工-研发人员工资'!B45 -> 0 | AG45: =COUNTIF(B45:AF45,"●")+COUNTIF(B45:AF45,"▲")+COUNTIF(B45:AF45,"■")+COUNTIF(B45:AF45,"★")+COUNTIF(B45:AF45,"◆")+COUNTIF(B45:AF45,"✽")+COUNTIF(B45:AF45,"❖")+COUNTIF(B45:AF45,"✪")+COUNTIF(B45:AF45,"✿")+COUNTIF(B45:AF45,"✤") -> 0 | AH45: =COUNTIF(B45:AF45,"●")+COUNTIF(B45:AF45,"▲")+COUNTIF(B45:AF45,"■")+COUNTIF(B45:AF45,"★")+COUNTIF(B45:AF45,"◆")+COUNTIF(B45:AF45,"✽")+COUNTIF(B45:AF45,"❖")+COUNTIF(B45:AF45,"✪")+COUNTIF(B45:AF45,"✿")+COUNTIF(B45:AF45,"✤")+COUNTIF(B45:AF45,"√") -> 0 | AI45: =AG45-'人员人工-研发人员工资'!E45 -> 0 | AJ45: =AH45-'人员人工-研发人员工资'!D45 -> 0
A46: ='人员人工-研发人员工资'!B46 -> 0 | AG46: =COUNTIF(B46:AF46,"●")+COUNTIF(B46:AF46,"▲")+COUNTIF(B46:AF46,"■")+COUNTIF(B46:AF46,"★")+COUNTIF(B46:AF46,"◆")+COUNTIF(B46:AF46,"✽")+COUNTIF(B46:AF46,"❖")+COUNTIF(B46:AF46,"✪")+COUNTIF(B46:AF46,"✿")+COUNTIF(B46:AF46,"✤") -> 0 | AH46: =COUNTIF(B46:AF46,"●")+COUNTIF(B46:AF46,"▲")+COUNTIF(B46:AF46,"■")+COUNTIF(B46:AF46,"★")+COUNTIF(B46:AF46,"◆")+COUNTIF(B46:AF46,"✽")+COUNTIF(B46:AF46,"❖")+COUNTIF(B46:AF46,"✪")+COUNTIF(B46:AF46,"✿")+COUNTIF(B46:AF46,"✤")+COUNTIF(B46:AF46,"√") -> 0 | AI46: =AG46-'人员人工-研发人员工资'!E46 -> 0 | AJ46: =AH46-'人员人工-研发人员工资'!D46 -> 0
A47: ='人员人工-研发人员工资'!B47 -> 0 | AG47: =COUNTIF(B47:AF47,"●")+COUNTIF(B47:AF47,"▲")+COUNTIF(B47:AF47,"■")+COUNTIF(B47:AF47,"★")+COUNTIF(B47:AF47,"◆")+COUNTIF(B47:AF47,"✽")+COUNTIF(B47:AF47,"❖")+COUNTIF(B47:AF47,"✪")+COUNTIF(B47:AF47,"✿")+COUNTIF(B47:AF47,"✤") -> 0 | AH47: =COUNTIF(B47:AF47,"●")+COUNTIF(B47:AF47,"▲")+COUNTIF(B47:AF47,"■")+COUNTIF(B47:AF47,"★")+COUNTIF(B47:AF47,"◆")+COUNTIF(B47:AF47,"✽")+COUNTIF(B47:AF47,"❖")+COUNTIF(B47:AF47,"✪")+COUNTIF(B47:AF47,"✿")+COUNTIF(B47:AF47,"✤")+COUNTIF(B47:AF47,"√") -> 0 | AI47: =AG47-'人员人工-研发人员工资'!E47 -> 0 | AJ47: =AH47-'人员人工-研发人员工资'!D47 -> 0
A48: ='人员人工-研发人员工资'!B48 -> 0 | AG48: =COUNTIF(B48:AF48,"●")+COUNTIF(B48:AF48,"▲")+COUNTIF(B48:AF48,"■")+COUNTIF(B48:AF48,"★")+COUNTIF(B48:AF48,"◆")+COUNTIF(B48:AF48,"✽")+COUNTIF(B48:AF48,"❖")+COUNTIF(B48:AF48,"✪")+COUNTIF(B48:AF48,"✿")+COUNTIF(B48:AF48,"✤") -> 0 | AH48: =COUNTIF(B48:AF48,"●")+COUNTIF(B48:AF48,"▲")+COUNTIF(B48:AF48,"■")+COUNTIF(B48:AF48,"★")+COUNTIF(B48:AF48,"◆")+COUNTIF(B48:AF48,"✽")+COUNTIF(B48:AF48,"❖")+COUNTIF(B48:AF48,"✪")+COUNTIF(B48:AF48,"✿")+COUNTIF(B48:AF48,"✤")+COUNTIF(B48:AF48,"√") -> 0 | AI48: =AG48-'人员人工-研发人员工资'!E48 -> 0 | AJ48: =AH48-'人员人工-研发人员工资'!D48 -> 0
A49: ='人员人工-研发人员工资'!B49 -> 0 | AG49: =COUNTIF(B49:AF49,"●")+COUNTIF(B49:AF49,"▲")+COUNTIF(B49:AF49,"■")+COUNTIF(B49:AF49,"★")+COUNTIF(B49:AF49,"◆")+COUNTIF(B49:AF49,"✽")+COUNTIF(B49:AF49,"❖")+COUNTIF(B49:AF49,"✪")+COUNTIF(B49:AF49,"✿")+COUNTIF(B49:AF49,"✤") -> 0 | AH49: =COUNTIF(B49:AF49,"●")+COUNTIF(B49:AF49,"▲")+COUNTIF(B49:AF49,"■")+COUNTIF(B49:AF49,"★")+COUNTIF(B49:AF49,"◆")+COUNTIF(B49:AF49,"✽")+COUNTIF(B49:AF49,"❖")+COUNTIF(B49:AF49,"✪")+COUNTIF(B49:AF49,"✿")+COUNTIF(B49:AF49,"✤")+COUNTIF(B49:AF49,"√") -> 0 | AI49: =AG49-'人员人工-研发人员工资'!E49 -> 0 | AJ49: =AH49-'人员人工-研发人员工资'!D49 -> 0
A50: ='人员人工-研发人员工资'!B50 -> 0 | AG50: =COUNTIF(B50:AF50,"●")+COUNTIF(B50:AF50,"▲")+COUNTIF(B50:AF50,"■")+COUNTIF(B50:AF50,"★")+COUNTIF(B50:AF50,"◆")+COUNTIF(B50:AF50,"✽")+COUNTIF(B50:AF50,"❖")+COUNTIF(B50:AF50,"✪")+COUNTIF(B50:AF50,"✿")+COUNTIF(B50:AF50,"✤") -> 0 | AH50: =COUNTIF(B50:AF50,"●")+COUNTIF(B50:AF50,"▲")+COUNTIF(B50:AF50,"■")+COUNTIF(B50:AF50,"★")+COUNTIF(B50:AF50,"◆")+COUNTIF(B50:AF50,"✽")+COUNTIF(B50:AF50,"❖")+COUNTIF(B50:AF50,"✪")+COUNTIF(B50:AF50,"✿")+COUNTIF(B50:AF50,"✤")+COUNTIF(B50:AF50,"√") -> 0 | AI50: =AG50-'人员人工-研发人员工资'!E50 -> 0 | AJ50: =AH50-'人员人工-研发人员工资'!D50 -> 0
A51: ='人员人工-研发人员工资'!B51 -> 0 | AG51: =COUNTIF(B51:AF51,"●")+COUNTIF(B51:AF51,"▲")+COUNTIF(B51:AF51,"■")+COUNTIF(B51:AF51,"★")+COUNTIF(B51:AF51,"◆")+COUNTIF(B51:AF51,"✽")+COUNTIF(B51:AF51,"❖")+COUNTIF(B51:AF51,"✪")+COUNTIF(B51:AF51,"✿")+COUNTIF(B51:AF51,"✤") -> 0 | AH51: =COUNTIF(B51:AF51,"●")+COUNTIF(B51:AF51,"▲")+COUNTIF(B51:AF51,"■")+COUNTIF(B51:AF51,"★")+COUNTIF(B51:AF51,"◆")+COUNTIF(B51:AF51,"✽")+COUNTIF(B51:AF51,"❖")+COUNTIF(B51:AF51,"✪")+COUNTIF(B51:AF51,"✿")+COUNTIF(B51:AF51,"✤")+COUNTIF(B51:AF51,"√") -> 0 | AI51: =AG51-'人员人工-研发人员工资'!E51 -> 0 | AJ51: =AH51-'人员人工-研发人员工资'!D51 -> 0
A52: ='人员人工-研发人员工资'!B52 -> 0 | AG52: =COUNTIF(B52:AF52,"●")+COUNTIF(B52:AF52,"▲")+COUNTIF(B52:AF52,"■")+COUNTIF(B52:AF52,"★")+COUNTIF(B52:AF52,"◆")+COUNTIF(B52:AF52,"✽")+COUNTIF(B52:AF52,"❖")+COUNTIF(B52:AF52,"✪")+COUNTIF(B52:AF52,"✿")+COUNTIF(B52:AF52,"✤") -> 0 | AH52: =COUNTIF(B52:AF52,"●")+COUNTIF(B52:AF52,"▲")+COUNTIF(B52:AF52,"■")+COUNTIF(B52:AF52,"★")+COUNTIF(B52:AF52,"◆")+COUNTIF(B52:AF52,"✽")+COUNTIF(B52:AF52,"❖")+COUNTIF(B52:AF52,"✪")+COUNTIF(B52:AF52,"✿")+COUNTIF(B52:AF52,"✤")+COUNTIF(B52:AF52,"√") -> 0 | AI52: =AG52-'人员人工-研发人员工资'!E52 -> 0 | AJ52: =AH52-'人员人工-研发人员工资'!D52 -> 0
A53: ='人员人工-研发人员工资'!B53 -> 0 | AG53: =COUNTIF(B53:AF53,"●")+COUNTIF(B53:AF53,"▲")+COUNTIF(B53:AF53,"■")+COUNTIF(B53:AF53,"★")+COUNTIF(B53:AF53,"◆")+COUNTIF(B53:AF53,"✽")+COUNTIF(B53:AF53,"❖")+COUNTIF(B53:AF53,"✪")+COUNTIF(B53:AF53,"✿")+COUNTIF(B53:AF53,"✤") -> 0 | AH53: =COUNTIF(B53:AF53,"●")+COUNTIF(B53:AF53,"▲")+COUNTIF(B53:AF53,"■")+COUNTIF(B53:AF53,"★")+COUNTIF(B53:AF53,"◆")+COUNTIF(B53:AF53,"✽")+COUNTIF(B53:AF53,"❖")+COUNTIF(B53:AF53,"✪")+COUNTIF(B53:AF53,"✿")+COUNTIF(B53:AF53,"✤")+COUNTIF(B53:AF53,"√") -> 0 | AI53: =AG53-'人员人工-研发人员工资'!E53 -> 0 | AJ53: =AH53-'人员人工-研发人员工资'!D53 -> 0
A54: ='人员人工-研发人员工资'!B54 -> 0 | AG54: =COUNTIF(B54:AF54,"●")+COUNTIF(B54:AF54,"▲")+COUNTIF(B54:AF54,"■")+COUNTIF(B54:AF54,"★")+COUNTIF(B54:AF54,"◆")+COUNTIF(B54:AF54,"✽")+COUNTIF(B54:AF54,"❖")+COUNTIF(B54:AF54,"✪")+COUNTIF(B54:AF54,"✿")+COUNTIF(B54:AF54,"✤") -> 0 | AH54: =COUNTIF(B54:AF54,"●")+COUNTIF(B54:AF54,"▲")+COUNTIF(B54:AF54,"■")+COUNTIF(B54:AF54,"★")+COUNTIF(B54:AF54,"◆")+COUNTIF(B54:AF54,"✽")+COUNTIF(B54:AF54,"❖")+COUNTIF(B54:AF54,"✪")+COUNTIF(B54:AF54,"✿")+COUNTIF(B54:AF54,"✤")+COUNTIF(B54:AF54,"√") -> 0 | AI54: =AG54-'人员人工-研发人员工资'!E54 -> 0 | AJ54: =AH54-'人员人工-研发人员工资'!D54 -> 0
A55: ='人员人工-研发人员工资'!B55 -> 0 | AG55: =COUNTIF(B55:AF55,"●")+COUNTIF(B55:AF55,"▲")+COUNTIF(B55:AF55,"■")+COUNTIF(B55:AF55,"★")+COUNTIF(B55:AF55,"◆")+COUNTIF(B55:AF55,"✽")+COUNTIF(B55:AF55,"❖")+COUNTIF(B55:AF55,"✪")+COUNTIF(B55:AF55,"✿")+COUNTIF(B55:AF55,"✤") -> 0 | AH55: =COUNTIF(B55:AF55,"●")+COUNTIF(B55:AF55,"▲")+COUNTIF(B55:AF55,"■")+COUNTIF(B55:AF55,"★")+COUNTIF(B55:AF55,"◆")+COUNTIF(B55:AF55,"✽")+COUNTIF(B55:AF55,"❖")+COUNTIF(B55:AF55,"✪")+COUNTIF(B55:AF55,"✿")+COUNTIF(B55:AF55,"✤")+COUNTIF(B55:AF55,"√") -> 0 | AI55: =AG55-'人员人工-研发人员工资'!E55 -> 0 | AJ55: =AH55-'人员人工-研发人员工资'!D55 -> 0
... A72: ='人员人工-研发人员工资'!B72 -> 0 | AG72: =COUNTIF(B72:AF72,"●")+COUNTIF(B72:AF72,"▲")+COUNTIF(B72:AF72,"■")+COUNTIF(B72:AF72,"★")+COUNTIF(B72:AF72,"◆")+COUNTIF(B72:AF72,"✽")+COUNTIF(B72:AF72,"❖")+COUNTIF(B72:AF72,"✪")+COUNTIF(B72:AF72,"✿")+COUNTIF(B72:AF72,"✤") -> 0 | AH72: =COUNTIF(B72:AF72,"●")+COUNTIF(B72:AF72,"▲")+COUNTIF(B72:AF72,"■")+COUNTIF(B72:AF72,"★")+COUNTIF(B72:AF72,"◆")+COUNTIF(B72:AF72,"✽")+COUNTIF(B72:AF72,"❖")+COUNTIF(B72:AF72,"✪")+COUNTIF(B72:AF72,"✿")+COUNTIF(B72:AF72,"✤")+COUNTIF(B72:AF72,"√") -> 0 | AI72: =AG72-'人员人工-研发人员工资'!E72 -> 0 | AJ72: =AH72-'人员人工-研发人员工资'!D72 -> 0
A73: 注： | B73: ● | C73: ▲ | D73: ■ | E73: ★ | F73: ◆ | G73: ✽ | H73: ❖ | I73: ✪ | J73: ✿ | K73: ✤ | L73: √ | M73: ×
B74: 1 | C74: 2 | D74: 3 | E74: 4 | F74: 5 | G74: 6 | H74: 7 | I74: 8 | J74: 9 | K74: 10 | L74: 其他出勤 | M74: 未出勤
A77: 2023年3月份研发人员考勤表
A79: 姓名 | B79: 星期三 | C79: 星期四 | D79: 星期五 | E79: 星期六 | F79: 星期日 | G79: 星期一 | H79: 星期二 | I79: 星期三 | J79: 星期四 | K79: 星期五 | L79: 星期六 | M79: 星期日 | N79: 星期一 | O79: 星期二 | P79: 星期三 | Q79: 星期四 | R79: 星期五 | S79: 星期六 | T79: 星期日 | U79: 星期一 | V79: 星期二 | W79: 星期三 | X79: 星期四 | Y79: 星期五 | Z79: 星期六 | AA79: 星期日 | AB79: 星期一 | AC79: 星期二 | AD79: 星期三 | AE79: 星期四 | AF79: 星期五 | AG79: 研发天数 | AH79: 出勤天数 | AI79: 研发天数验证 | AJ79: 出勤天数验证
...

Sheet 人员人工-研发人员社保
B1: 2025年1月份研发人员社保项目分摊表
A3: 序号 | B3: 姓名 | C3: 月社保 | D3: 出勤天数 | E3: 研发天数合计 | F3: 研发社保合计 | G3: =立项!$A$3 -> RD01 | I3: =立项!$A$4 -> RD02 | K3: =立项!$A$5 -> RD03 | M3: =立项!$A$6 -> RD04 | O3: =立项!$A$7 -> RD05 | Q3: =立项!$A$8 -> RD06 | S3: =立项!$A$9 -> RD07 | U3: =立项!$A$10 -> RD08 | W3: =立项!$A$11 -> RD09 | Y3: =立项!$A$12 -> RD10
G4: =立项!C3 -> 0 | I4: =立项!C4 -> 0 | K4: =立项!C5 -> 0 | M4: =立项!C6 -> 0 | O4: =立项!C7 -> 0 | Q4: =立项!C8 -> 0 | S4: =立项!C9 -> 0 | U4: =立项!C10 -> 0 | W4: =立项!C11 -> 0 | Y4: =立项!C12 -> 0
G5: 研发天数 | H5: 研发社保 | I5: 研发天数 | J5: 研发社保 | K5: 研发天数 | L5: 研发社保 | M5: 研发天数 | N5: 研发社保 | O5: 研发天数 | P5: 研发社保 | Q5: 研发天数 | R5: 研发社保 | S5: 研发天数 | T5: 研发社保 | U5: 研发天数 | V5: 研发社保 | W5: 研发天数 | X5: 研发社保 | Y5: 研发天数 | Z5: 研发社保
A6: 1 | B6: ='人员人工-研发人员工资'!B6 -> 0 | D6: ='人员人工-研发人员工资'!D6 -> 0 | E6: =G6+I6+K6+M6+O6+Q6+S6+U6+W6+Y6 -> 0 | F6: =H6+J6+L6+N6+P6+R6+T6+V6+X6+Z6 -> 0 | G6: ='人员人工-研发人员工资'!G6 -> 0 | H6: =IF($D6=0,0,ROUND(G6/$D6*$C6,2)) -> 0 | I6: ='人员人工-研发人员工资'!I6 -> 0 | J6: =IF($D6=0,0,ROUND(I6/$D6*$C6,2)) -> 0 | K6: ='人员人工-研发人员工资'!K6 -> 0 | L6: =IF($D6=0,0,ROUND(K6/$D6*$C6,2)) -> 0 | M6: ='人员人工-研发人员工资'!M6 -> 0 | N6: =IF($D6=0,0,ROUND(M6/$D6*$C6,2)) -> 0 | O6: ='人员人工-研发人员工资'!O6 -> 0 | P6: =IF($D6=0,0,ROUND(O6/$D6*$C6,2)) -> 0 | Q6: ='人员人工-研发人员工资'!Q6 -> 0 | R6: =IF($D6=0,0,ROUND(Q6/$D6*$C6,2)) -> 0 | S6: ='人员人工-研发人员工资'!S6 -> 0 | T6: =IF($D6=0,0,ROUND(S6/$D6*$C6,2)) -> 0 | U6: ='人员人工-研发人员工资'!U6 -> 0 | V6: =IF($D6=0,0,ROUND(U6/$D6*$C6,2)) -> 0 | W6: ='人员人工-研发人员工资'!W6 -> 0 | X6: =IF($D6=0,0,ROUND(W6/$D6*$C6,2)) -> 0 | Y6: ='人员人工-研发人员工资'!Y6 -> 0 | Z6: =IF($D6=0,0,ROUND(Y6/$D6*$C6,2)) -> 0
A7: 2 | B7: ='人员人工-研发人员工资'!B7 -> 0 | D7: ='人员人工-研发人员工资'!D7 -> 0 | E7: =G7+I7+K7+M7+O7+Q7+S7+U7+W7+Y7 -> 0 | F7: =H7+J7+L7+N7+P7+R7+T7+V7+X7+Z7 -> 0 | G7: ='人员人工-研发人员工资'!G7 -> 0 | H7: =IF($D7=0,0,ROUND(G7/$D7*$C7,2)) -> 0 | I7: ='人员人工-研发人员工资'!I7 -> 0 | J7: =IF($D7=0,0,ROUND(I7/$D7*$C7,2)) -> 0 | K7: ='人员人工-研发人员工资'!K7 -> 0 | L7: =IF($D7=0,0,ROUND(K7/$D7*$C7,2)) -> 0 | M7: ='人员人工-研发人员工资'!M7 -> 0 | N7: =IF($D7=0,0,ROUND(M7/$D7*$C7,2)) -> 0 | O7: ='人员人工-研发人员工资'!O7 -> 0 | P7: =IF($D7=0,0,ROUND(O7/$D7*$C7,2)) -> 0 | Q7: ='人员人工-研发人员工资'!Q7 -> 0 | R7: =IF($D7=0,0,ROUND(Q7/$D7*$C7,2)) -> 0 | S7: ='人员人工-研发人员工资'!S7 -> 0 | T7: =IF($D7=0,0,ROUND(S7/$D7*$C7,2)) -> 0 | U7: ='人员人工-研发人员工资'!U7 -> 0 | V7: =IF($D7=0,0,ROUND(U7/$D7*$C7,2)) -> 0 | W7: ='人员人工-研发人员工资'!W7 -> 0 | X7: =IF($D7=0,0,ROUND(W7/$D7*$C7,2)) -> 0 | Y7: ='人员人工-研发人员工资'!Y7 -> 0 | Z7: =IF($D7=0,0,ROUND(Y7/$D7*$C7,2)) -> 0
A8: 3 | B8: ='人员人工-研发人员工资'!B8 -> 0 | D8: ='人员人工-研发人员工资'!D8 -> 0 | E8: =G8+I8+K8+M8+O8+Q8+S8+U8+W8+Y8 -> 0 | F8: =H8+J8+L8+N8+P8+R8+T8+V8+X8+Z8 -> 0 | G8: ='人员人工-研发人员工资'!G8 -> 0 | H8: =IF($D8=0,0,ROUND(G8/$D8*$C8,2)) -> 0 | I8: ='人员人工-研发人员工资'!I8 -> 0 | J8: =IF($D8=0,0,ROUND(I8/$D8*$C8,2)) -> 0 | K8: ='人员人工-研发人员工资'!K8 -> 0 | L8: =IF($D8=0,0,ROUND(K8/$D8*$C8,2)) -> 0 | M8: ='人员人工-研发人员工资'!M8 -> 0 | N8: =IF($D8=0,0,ROUND(M8/$D8*$C8,2)) -> 0 | O8: ='人员人工-研发人员工资'!O8 -> 0 | P8: =IF($D8=0,0,ROUND(O8/$D8*$C8,2)) -> 0 | Q8: ='人员人工-研发人员工资'!Q8 -> 0 | R8: =IF($D8=0,0,ROUND(Q8/$D8*$C8,2)) -> 0 | S8: ='人员人工-研发人员工资'!S8 -> 0 | T8: =IF($D8=0,0,ROUND(S8/$D8*$C8,2)) -> 0 | U8: ='人员人工-研发人员工资'!U8 -> 0 | V8: =IF($D8=0,0,ROUND(U8/$D8*$C8,2)) -> 0 | W8: ='人员人工-研发人员工资'!W8 -> 0 | X8: =IF($D8=0,0,ROUND(W8/$D8*$C8,2)) -> 0 | Y8: ='人员人工-研发人员工资'!Y8 -> 0 | Z8: =IF($D8=0,0,ROUND(Y8/$D8*$C8,2)) -> 0
A9: 4 | B9: ='人员人工-研发人员工资'!B9 -> 0 | D9: ='人员人工-研发人员工资'!D9 -> 0 | E9: =G9+I9+K9+M9+O9+Q9+S9+U9+W9+Y9 -> 0 | F9: =H9+J9+L9+N9+P9+R9+T9+V9+X9+Z9 -> 0 | G9: ='人员人工-研发人员工资'!G9 -> 0 | H9: =IF($D9=0,0,ROUND(G9/$D9*$C9,2)) -> 0 | I9: ='人员人工-研发人员工资'!I9 -> 0 | J9: =IF($D9=0,0,ROUND(I9/$D9*$C9,2)) -> 0 | K9: ='人员人工-研发人员工资'!K9 -> 0 | L9: =IF($D9=0,0,ROUND(K9/$D9*$C9,2)) -> 0 | M9: ='人员人工-研发人员工资'!M9 -> 0 | N9: =IF($D9=0,0,ROUND(M9/$D9*$C9,2)) -> 0 | O9: ='人员人工-研发人员工资'!O9 -> 0 | P9: =IF($D9=0,0,ROUND(O9/$D9*$C9,2)) -> 0 | Q9: ='人员人工-研发人员工资'!Q9 -> 0 | R9: =IF($D9=0,0,ROUND(Q9/$D9*$C9,2)) -> 0 | S9: ='人员人工-研发人员工资'!S9 -> 0 | T9: =IF($D9=0,0,ROUND(S9/$D9*$C9,2)) -> 0 | U9: ='人员人工-研发人员工资'!U9 -> 0 | V9: =IF($D9=0,0,ROUND(U9/$D9*$C9,2)) -> 0 | W9: ='人员人工-研发人员工资'!W9 -> 0 | X9: =IF($D9=0,0,ROUND(W9/$D9*$C9,2)) -> 0 | Y9: ='人员人工-研发人员工资'!Y9 -> 0 | Z9: =IF($D9=0,0,ROUND(Y9/$D9*$C9,2)) -> 0
A10: 5 | B10: ='人员人工-研发人员工资'!B10 -> 0 | D10: ='人员人工-研发人员工资'!D10 -> 0 | E10: =G10+I10+K10+M10+O10+Q10+S10+U10+W10+Y10 -> 0 | F10: =H10+J10+L10+N10+P10+R10+T10+V10+X10+Z10 -> 0 | G10: ='人员人工-研发人员工资'!G10 -> 0 | H10: =IF($D10=0,0,ROUND(G10/$D10*$C10,2)) -> 0 | I10: ='人员人工-研发人员工资'!I10 -> 0 | J10: =IF($D10=0,0,ROUND(I10/$D10*$C10,2)) -> 0 | K10: ='人员人工-研发人员工资'!K10 -> 0 | L10: =IF($D10=0,0,ROUND(K10/$D10*$C10,2)) -> 0 | M10: ='人员人工-研发人员工资'!M10 -> 0 | N10: =IF($D10=0,0,ROUND(M10/$D10*$C10,2)) -> 0 | O10: ='人员人工-研发人员工资'!O10 -> 0 | P10: =IF($D10=0,0,ROUND(O10/$D10*$C10,2)) -> 0 | Q10: ='人员人工-研发人员工资'!Q10 -> 0 | R10: =IF($D10=0,0,ROUND(Q10/$D10*$C10,2)) -> 0 | S10: ='人员人工-研发人员工资'!S10 -> 0 | T10: =IF($D10=0,0,ROUND(S10/$D10*$C10,2)) -> 0 | U10: ='人员人工-研发人员工资'!U10 -> 0 | V10: =IF($D10=0,0,ROUND(U10/$D10*$C10,2)) -> 0 | W10: ='人员人工-研发人员工资'!W10 -> 0 | X10: =IF($D10=0,0,ROUND(W10/$D10*$C10,2)) -> 0 | Y10: ='人员人工-研发人员工资'!Y10 -> 0 | Z10: =IF($D10=0,0,ROUND(Y10/$D10*$C10,2)) -> 0
A11: 6 | B11: ='人员人工-研发人员工资'!B11 -> 0 | D11: ='人员人工-研发人员工资'!D11 -> 0 | E11: =G11+I11+K11+M11+O11+Q11+S11+U11+W11+Y11 -> 0 | F11: =H11+J11+L11+N11+P11+R11+T11+V11+X11+Z11 -> 0 | G11: ='人员人工-研发人员工资'!G11 -> 0 | H11: =IF($D11=0,0,ROUND(G11/$D11*$C11,2)) -> 0 | I11: ='人员人工-研发人员工资'!I11 -> 0 | J11: =IF($D11=0,0,ROUND(I11/$D11*$C11,2)) -> 0 | K11: ='人员人工-研发人员工资'!K11 -> 0 | L11: =IF($D11=0,0,ROUND(K11/$D11*$C11,2)) -> 0 | M11: ='人员人工-研发人员工资'!M11 -> 0 | N11: =IF($D11=0,0,ROUND(M11/$D11*$C11,2)) -> 0 | O11: ='人员人工-研发人员工资'!O11 -> 0 | P11: =IF($D11=0,0,ROUND(O11/$D11*$C11,2)) -> 0 | Q11: ='人员人工-研发人员工资'!Q11 -> 0 | R11: =IF($D11=0,0,ROUND(Q11/$D11*$C11,2)) -> 0 | S11: ='人员人工-研发人员工资'!S11 -> 0 | T11: =IF($D11=0,0,ROUND(S11/$D11*$C11,2)) -> 0 | U11: ='人员人工-研发人员工资'!U11 -> 0 | V11: =IF($D11=0,0,ROUND(U11/$D11*$C11,2)) -> 0 | W11: ='人员人工-研发人员工资'!W11 -> 0 | X11: =IF($D11=0,0,ROUND(W11/$D11*$C11,2)) -> 0 | Y11: ='人员人工-研发人员工资'!Y11 -> 0 | Z11: =IF($D11=0,0,ROUND(Y11/$D11*$C11,2)) -> 0
A12: 7 | B12: ='人员人工-研发人员工资'!B12 -> 0 | D12: ='人员人工-研发人员工资'!D12 -> 0 | E12: =G12+I12+K12+M12+O12+Q12+S12+U12+W12+Y12 -> 0 | F12: =H12+J12+L12+N12+P12+R12+T12+V12+X12+Z12 -> 0 | G12: ='人员人工-研发人员工资'!G12 -> 0 | H12: =IF($D12=0,0,ROUND(G12/$D12*$C12,2)) -> 0 | I12: ='人员人工-研发人员工资'!I12 -> 0 | J12: =IF($D12=0,0,ROUND(I12/$D12*$C12,2)) -> 0 | K12: ='人员人工-研发人员工资'!K12 -> 0 | L12: =IF($D12=0,0,ROUND(K12/$D12*$C12,2)) -> 0 | M12: ='人员人工-研发人员工资'!M12 -> 0 | N12: =IF($D12=0,0,ROUND(M12/$D12*$C12,2)) -> 0 | O12: ='人员人工-研发人员工资'!O12 -> 0 | P12: =IF($D12=0,0,ROUND(O12/$D12*$C12,2)) -> 0 | Q12: ='人员人工-研发人员工资'!Q12 -> 0 | R12: =IF($D12=0,0,ROUND(Q12/$D12*$C12,2)) -> 0 | S12: ='人员人工-研发人员工资'!S12 -> 0 | T12: =IF($D12=0,0,ROUND(S12/$D12*$C12,2)) -> 0 | U12: ='人员人工-研发人员工资'!U12 -> 0 | V12: =IF($D12=0,0,ROUND(U12/$D12*$C12,2)) -> 0 | W12: ='人员人工-研发人员工资'!W12 -> 0 | X12: =IF($D12=0,0,ROUND(W12/$D12*$C12,2)) -> 0 | Y12: ='人员人工-研发人员工资'!Y12 -> 0 | Z12: =IF($D12=0,0,ROUND(Y12/$D12*$C12,2)) -> 0
A13: 8 | B13: ='人员人工-研发人员工资'!B13 -> 0 | D13: ='人员人工-研发人员工资'!D13 -> 0 | E13: =G13+I13+K13+M13+O13+Q13+S13+U13+W13+Y13 -> 0 | F13: =H13+J13+L13+N13+P13+R13+T13+V13+X13+Z13 -> 0 | G13: ='人员人工-研发人员工资'!G13 -> 0 | H13: =IF($D13=0,0,ROUND(G13/$D13*$C13,2)) -> 0 | I13: ='人员人工-研发人员工资'!I13 -> 0 | J13: =IF($D13=0,0,ROUND(I13/$D13*$C13,2)) -> 0 | K13: ='人员人工-研发人员工资'!K13 -> 0 | L13: =IF($D13=0,0,ROUND(K13/$D13*$C13,2)) -> 0 | M13: ='人员人工-研发人员工资'!M13 -> 0 | N13: =IF($D13=0,0,ROUND(M13/$D13*$C13,2)) -> 0 | O13: ='人员人工-研发人员工资'!O13 -> 0 | P13: =IF($D13=0,0,ROUND(O13/$D13*$C13,2)) -> 0 | Q13: ='人员人工-研发人员工资'!Q13 -> 0 | R13: =IF($D13=0,0,ROUND(Q13/$D13*$C13,2)) -> 0 | S13: ='人员人工-研发人员工资'!S13 -> 0 | T13: =IF($D13=0,0,ROUND(S13/$D13*$C13,2)) -> 0 | U13: ='人员人工-研发人员工资'!U13 -> 0 | V13: =IF($D13=0,0,ROUND(U13/$D13*$C13,2)) -> 0 | W13: ='人员人工-研发人员工资'!W13 -> 0 | X13: =IF($D13=0,0,ROUND(W13/$D13*$C13,2)) -> 0 | Y13: ='人员人工-研发人员工资'!Y13 -> 0 | Z13: =IF($D13=0,0,ROUND(Y13/$D13*$C13,2)) -> 0
A14: 9 | B14: ='人员人工-研发人员工资'!B14 -> 0 | D14: ='人员人工-研发人员工资'!D14 -> 0 | E14: =G14+I14+K14+M14+O14+Q14+S14+U14+W14+Y14 -> 0 | F14: =H14+J14+L14+N14+P14+R14+T14+V14+X14+Z14 -> 0 | G14: ='人员人工-研发人员工资'!G14 -> 0 | H14: =IF($D14=0,0,ROUND(G14/$D14*$C14,2)) -> 0 | I14: ='人员人工-研发人员工资'!I14 -> 0 | J14: =IF($D14=0,0,ROUND(I14/$D14*$C14,2)) -> 0 | K14: ='人员人工-研发人员工资'!K14 -> 0 | L14: =IF($D14=0,0,ROUND(K14/$D14*$C14,2)) -> 0 | M14: ='人员人工-研发人员工资'!M14 -> 0 | N14: =IF($D14=0,0,ROUND(M14/$D14*$C14,2)) -> 0 | O14: ='人员人工-研发人员工资'!O14 -> 0 | P14: =IF($D14=0,0,ROUND(O14/$D14*$C14,2)) -> 0 | Q14: ='人员人工-研发人员工资'!Q14 -> 0 | R14: =IF($D14=0,0,ROUND(Q14/$D14*$C14,2)) -> 0 | S14: ='人员人工-研发人员工资'!S14 -> 0 | T14: =IF($D14=0,0,ROUND(S14/$D14*$C14,2)) -> 0 | U14: ='人员人工-研发人员工资'!U14 -> 0 | V14: =IF($D14=0,0,ROUND(U14/$D14*$C14,2)) -> 0 | W14: ='人员人工-研发人员工资'!W14 -> 0 | X14: =IF($D14=0,0,ROUND(W14/$D14*$C14,2)) -> 0 | Y14: ='人员人工-研发人员工资'!Y14 -> 0 | Z14: =IF($D14=0,0,ROUND(Y14/$D14*$C14,2)) -> 0
A15: 10 | B15: ='人员人工-研发人员工资'!B15 -> 0 | D15: ='人员人工-研发人员工资'!D15 -> 0 | E15: =G15+I15+K15+M15+O15+Q15+S15+U15+W15+Y15 -> 0 | F15: =H15+J15+L15+N15+P15+R15+T15+V15+X15+Z15 -> 0 | G15: ='人员人工-研发人员工资'!G15 -> 0 | H15: =IF($D15=0,0,ROUND(G15/$D15*$C15,2)) -> 0 | I15: ='人员人工-研发人员工资'!I15 -> 0 | J15: =IF($D15=0,0,ROUND(I15/$D15*$C15,2)) -> 0 | K15: ='人员人工-研发人员工资'!K15 -> 0 | L15: =IF($D15=0,0,ROUND(K15/$D15*$C15,2)) -> 0 | M15: ='人员人工-研发人员工资'!M15 -> 0 | N15: =IF($D15=0,0,ROUND(M15/$D15*$C15,2)) -> 0 | O15: ='人员人工-研发人员工资'!O15 -> 0 | P15: =IF($D15=0,0,ROUND(O15/$D15*$C15,2)) -> 0 | Q15: ='人员人工-研发人员工资'!Q15 -> 0 | R15: =IF($D15=0,0,ROUND(Q15/$D15*$C15,2)) -> 0 | S15: ='人员人工-研发人员工资'!S15 -> 0 | T15: =IF($D15=0,0,ROUND(S15/$D15*$C15,2)) -> 0 | U15: ='人员人工-研发人员工资'!U15 -> 0 | V15: =IF($D15=0,0,ROUND(U15/$D15*$C15,2)) -> 0 | W15: ='人员人工-研发人员工资'!W15 -> 0 | X15: =IF($D15=0,0,ROUND(W15/$D15*$C15,2)) -> 0 | Y15: ='人员人工-研发人员工资'!Y15 -> 0 | Z15: =IF($D15=0,0,ROUND(Y15/$D15*$C15,2)) -> 0
A16: 11 | B16: ='人员人工-研发人员工资'!B16 -> 0 | D16: ='人员人工-研发人员工资'!D16 -> 0 | E16: =G16+I16+K16+M16+O16+Q16+S16+U16+W16+Y16 -> 0 | F16: =H16+J16+L16+N16+P16+R16+T16+V16+X16+Z16 -> 0 | G16: ='人员人工-研发人员工资'!G16 -> 0 | H16: =IF($D16=0,0,ROUND(G16/$D16*$C16,2)) -> 0 | I16: ='人员人工-研发人员工资'!I16 -> 0 | J16: =IF($D16=0,0,ROUND(I16/$D16*$C16,2)) -> 0 | K16: ='人员人工-研发人员工资'!K16 -> 0 | L16: =IF($D16=0,0,ROUND(K16/$D16*$C16,2)) -> 0 | M16: ='人员人工-研发人员工资'!M16 -> 0 | N16: =IF($D16=0,0,ROUND(M16/$D16*$C16,2)) -> 0 | O16: ='人员人工-研发人员工资'!O16 -> 0 | P16: =IF($D16=0,0,ROUND(O16/$D16*$C16,2)) -> 0 | Q16: ='人员人工-研发人员工资'!Q16 -> 0 | R16: =IF($D16=0,0,ROUND(Q16/$D16*$C16,2)) -> 0 | S16: ='人员人工-研发人员工资'!S16 -> 0 | T16: =IF($D16=0,0,ROUND(S16/$D16*$C16,2)) -> 0 | U16: ='人员人工-研发人员工资'!U16 -> 0 | V16: =IF($D16=0,0,ROUND(U16/$D16*$C16,2)) -> 0 | W16: ='人员人工-研发人员工资'!W16 -> 0 | X16: =IF($D16=0,0,ROUND(W16/$D16*$C16,2)) -> 0 | Y16: ='人员人工-研发人员工资'!Y16 -> 0 | Z16: =IF($D16=0,0,ROUND(Y16/$D16*$C16,2)) -> 0
